<?xml version="1.0"?>
<robot name="pointRobot">
  <!--colors-->
  <material name="blue">
      <color rgba="0 0 0.8 1"/>
  </material>
  <material name="red">
      <color rgba="0.8 0 0.0 1"/>
  </material>
  <material name="transparent_red">
      <color rgba="0.8 0 0.0 0.2"/>
  </material>
  <material name="darkgrey">
      <color rgba="0.502 0.502 0.502 1.0"/>
  </material>
  <material name="lightgrey">
      <color rgba="0.402 0.402 0.402 0.9"/>
  </material>
  <!--links-->
  <link name="world"/>
  <link name="odom"/>
  <link name="base_link_x">
    <inertial>
      <mass value="1.0"/>
      <origin rpy="0 0 0" xyz="0 0 0"/>
      <inertia ixx="1.0" ixy="0.0" ixz="0.0" iyy="1.0" iyz="0.0" izz="1.0"/>
    </inertial>
  </link>
  <link name="base_link_y">
    <inertial>
      <mass value="1.0"/>
      <origin rpy="0 0 0" xyz="0 0 0"/>
      <inertia ixx="1.0" ixy="0.0" ixz="0.0" iyy="1.0" iyz="0.0" izz="1.0"/>
    </inertial>
  </link>
  <link name="base_link">
    <inertial>
      <mass value="100.0"/>
      <origin rpy="0 0 0" xyz="0 0 0"/>
      <inertia ixx="1.0" ixy="0.0" ixz="0.0" iyy="1.0" iyz="0.0" izz="1.0"/>
    </inertial>
    <collision>
      <origin rpy="0.0 0 0" xyz="0 0 0"/>
      <geometry>
        <box size='0.61 0.33 0.13'/>
      </geometry>
    </collision>
    <visual>
      <origin rpy="0.0 0 0" xyz="0 0 0"/>
      <geometry>
        <box size='0.61 0.33 0.13'/>
      </geometry>
      <material name="lightgrey"/>
    </visual>
  </link>
  <link name="pole_link">
    <inertial>
      <mass value="100.0"/>
      <origin rpy="0 0 0" xyz="0 0 0"/>
      <inertia ixx="1.0" ixy="0.0" ixz="0.0" iyy="1.0" iyz="0.0" izz="1.0"/>
    </inertial>
    <collision>
      <origin rpy="0.0 0 0" xyz="0 0 0"/>
      <geometry>
          <cylinder length="0.43" radius="0.02"/>
      </geometry>
    </collision>
    <visual>
      <origin rpy="0.0 0 0" xyz="0 0 0"/>
      <geometry>
          <cylinder length="0.43" radius="0.02"/>
      </geometry>
      <material name="darkgrey"/>
    </visual>
  </link>
  <link name="platform_link">
    <inertial>
      <mass value="100.0"/>
      <origin rpy="0 0 0" xyz="0 0 0"/>
      <inertia ixx="1.0" ixy="0.0" ixz="0.0" iyy="1.0" iyz="0.0" izz="1.0"/>
    </inertial>
    <collision>
      <origin rpy="0.0 0 0" xyz="0 0 0"/>
      <geometry>
          <cylinder length="0.05" radius="0.05"/>
      </geometry>
    </collision>
    <visual>
      <origin rpy="0.0 0 0" xyz="0 0 0"/>
      <geometry>
          <cylinder length="0.05" radius="0.05"/>
      </geometry>
      <material name="darkgrey"/>
    </visual>
  </link>
  <link name="front_link">
    <inertial>
      <mass value="0.01"/>
      <origin rpy="0 0 0" xyz="0 0 0"/>
      <inertia ixx="1.0" ixy="0.0" ixz="0.0" iyy="1.0" iyz="0.0" izz="1.0"/>
    </inertial>
    <visual>
      <origin rpy="0.0 0 0" xyz="0 0 0"/>
      <geometry>
          <sphere radius="0.02"/>
      </geometry>
      <material name="red"/>
    </visual>
  </link>
  <link name="lidar_sensor_link">
    <inertial>
      <mass value="0.01"/>
      <origin rpy="0 0 0" xyz="0 0 0"/>
      <inertia ixx="1.0" ixy="0.0" ixz="0.0" iyy="1.0" iyz="0.0" izz="1.0"/>
    </inertial>
  </link>
  <!--collision links-->
  <link name="collision_link_front_right">
    <inertial>
      <mass value="0.01"/>
      <origin rpy="0 0 0" xyz="0 0 0"/>
      <inertia ixx="1.0" ixy="0.0" ixz="0.0" iyy="1.0" iyz="0.0" izz="1.0"/>
    </inertial>
    <visual>
      <origin rpy="0.0 0 0" xyz="0 0 0"/>
      <geometry>
        <sphere radius='0.12'/>
      </geometry>
      <material name="transparent_red"/>
    </visual>
  </link>
  <link name="collision_link_front_left">
    <inertial>
      <mass value="0.01"/>
      <origin rpy="0 0 0" xyz="0 0 0"/>
      <inertia ixx="1.0" ixy="0.0" ixz="0.0" iyy="1.0" iyz="0.0" izz="1.0"/>
    </inertial>
    <visual>
      <origin rpy="0.0 0 0" xyz="0 0 0"/>
      <geometry>
        <sphere radius='0.12'/>
      </geometry>
      <material name="transparent_red"/>
    </visual>
  </link>
  <link name="collision_link_center_right">
    <inertial>
      <mass value="0.01"/>
      <origin rpy="0 0 0" xyz="0 0 0"/>
      <inertia ixx="1.0" ixy="0.0" ixz="0.0" iyy="1.0" iyz="0.0" izz="1.0"/>
    </inertial>
    <visual>
      <origin rpy="0.0 0 0" xyz="0 0 0"/>
      <geometry>
        <sphere radius='0.20'/>
      </geometry>
      <material name="transparent_red"/>
    </visual>
  </link>
  <link name="collision_link_center_left">
    <inertial>
      <mass value="0.01"/>
      <origin rpy="0 0 0" xyz="0 0 0"/>
      <inertia ixx="1.0" ixy="0.0" ixz="0.0" iyy="1.0" iyz="0.0" izz="1.0"/>
    </inertial>
    <visual>
      <origin rpy="0.0 0 0" xyz="0 0 0"/>
      <geometry>
        <sphere radius='0.20'/>
      </geometry>
      <material name="transparent_red"/>
    </visual>
  </link>
  <link name="collision_link_rear_right">
    <inertial>
      <mass value="0.01"/>
      <origin rpy="0 0 0" xyz="0 0 0"/>
      <inertia ixx="1.0" ixy="0.0" ixz="0.0" iyy="1.0" iyz="0.0" izz="1.0"/>
    </inertial>
    <visual>
      <origin rpy="0.0 0 0" xyz="0 0 0"/>
      <geometry>
        <sphere radius='0.12'/>
      </geometry>
      <material name="transparent_red"/>
    </visual>
  </link>
  <link name="collision_link_rear_left">
    <inertial>
      <mass value="0.01"/>
      <origin rpy="0 0 0" xyz="0 0 0"/>
      <inertia ixx="1.0" ixy="0.0" ixz="0.0" iyy="1.0" iyz="0.0" izz="1.0"/>
    </inertial>
    <visual>
      <origin rpy="0.0 0 0" xyz="0 0 0"/>
      <geometry>
        <sphere radius='0.12'/>
      </geometry>
      <material name="transparent_red"/>
    </visual>
  </link>
  <!--joints-->
  <joint name="odom_joint" type='fixed'>
    <parent link="world"/>
    <child link="odom"/>
    <origin rpy="0 0 0" xyz="0 0 0"/>
  </joint>
  <joint name="mobile_joint_x" type="prismatic">
    <safety_controller k_position="100.0" k_velocity="40.0" soft_lower_limit="-2.8973" soft_upper_limit="2.8973"/>
    <parent link="odom"/>
    <child link="base_link_x"/>
    <origin rpy="0 0 0" xyz="0 0 0.05"/>
    <axis xyz="1 0 0"/>
    <limit effort="87" lower="-5" upper="5" velocity="2.1750"/>
  </joint>
  <joint name="mobile_joint_y" type="prismatic">
    <safety_controller k_position="100.0" k_velocity="40.0" soft_lower_limit="-2.8973" soft_upper_limit="2.8973"/>
    <parent link="base_link_x"/>
    <child link="base_link_y"/>
    <origin rpy="0 0 0" xyz="0 0 0"/>
    <axis xyz="0 1 0"/>
    <limit effort="87" lower="-5" upper="5" velocity="2.1750"/>
  </joint>
  <joint name="mobile_joint_theta" type="revolute">
    <parent link="base_link_y"/>
    <child link="base_link"/>
    <origin rpy="0 0 0" xyz="0 0 0"/>
    <axis xyz="0 0 1"/>
    <limit effort="87" lower="-5" upper="5" velocity="2.1750"/>
  </joint>
  <joint name="robot_pole_joint" type="fixed">
    <parent link="base_link"/>
    <child link="pole_link"/>
    <origin rpy="0 0 0" xyz="0 0 0.1"/>
  </joint>
  <joint name="platform_joint" type="fixed">
    <parent link="pole_link"/>
    <child link="platform_link"/>
    <origin rpy="0 0 0" xyz="0 0 0.2"/>
  </joint>
  <joint name="lidar_sensor_joint" type="fixed">
    <parent link="platform_link"/>
    <child link="lidar_sensor_link"/>
    <origin rpy="0 0 0" xyz="0 0 0.1"/>
  </joint>
  <joint name="front_link_joint" type='fixed'>
    <parent link="base_link"/>
    <child link="front_link"/>
    <origin rpy="0 0 0" xyz="0.31 0.0 0.05"/>
  </joint>
  <joint name="collision_front_right_joint" type='fixed'>
    <parent link="base_link"/>
    <child link="collision_link_front_right"/>
    <origin rpy="0 0 0" xyz="0.22 0.13 0.0"/>
  </joint>
  <joint name="collision_front_left_joint" type='fixed'>
    <parent link="base_link"/>
    <child link="collision_link_front_left"/>
    <origin rpy="0 0 0" xyz="0.22 -0.13 0.0"/>
  </joint>
  <joint name="collision_center_right_joint" type='fixed'>
    <parent link="base_link"/>
    <child link="collision_link_center_right"/>
    <origin rpy="0 0 0" xyz="0.0 0.13 0.0"/>
  </joint>
  <joint name="collision_center_left_joint" type='fixed'>
    <parent link="base_link"/>
    <child link="collision_link_center_left"/>
    <origin rpy="0 0 0" xyz="0.0 -0.13 0.0"/>
  </joint>
  <joint name="collision_rear_right_joint" type='fixed'>
    <parent link="base_link"/>
    <child link="collision_link_rear_right"/>
    <origin rpy="0 0 0" xyz="-0.22 0.13 0.0"/>
  </joint>
  <joint name="collision_rear_left_joint" type='fixed'>
    <parent link="base_link"/>
    <child link="collision_link_rear_left"/>
    <origin rpy="0 0 0" xyz="-0.22 -0.13 0.0"/>
  </joint>
  
</robot>
