<?xml version="1.0"?>
<!-- =================================================================================== -->
<!-- |    This document was autogenerated by xacro from panda.urdf.xacro               | -->
<!-- |    EDITING THIS FILE BY HAND IS NOT RECOMMENDED                                 | -->
<!-- =================================================================================== -->
<robot name="panda_description">
  <link name="world"/>
  <joint name="robot_to_world" type="fixed">
    <parent link="world"/>
    <child link="panda_link0"/>
    <origin rpy="0.0 0.0 0.0" xyz="0.0 0.0 0.1"/>
  </joint>
  <!-- end for simulation -->
  <link name="panda_link0">
    <visual>
      <geometry>
        <sphere radius="0.1"/>
      </geometry>
    </visual>
    <collision>
      <geometry>
        <sphere radius="0.1"/>
      </geometry>
    </collision>
    <!-- for simulation -->
    <inertial>
      <origin rpy="0 0 0" xyz="0 0 0.05"/>
      <mass value="1.00"/>
      <inertia ixx="0.25083" ixy="0.0" ixz="0.0" iyy="0.25083" iyz="0.0" izz="0.5"/>
    </inertial>
    <!-- end for simulation -->
  </link>
  <link name="panda_link1">
    <visual>
      <origin xyz="0 0 0.6" rpy="0 0 0"/>
      <geometry>
        <cylinder length="1.0" radius="0.1"/>
      </geometry>
    </visual>
    <collision>
      <origin xyz="0 0 0.6" rpy="0 0 0"/>
      <geometry>
        <cylinder length="1.0" radius="0.1"/>
      </geometry>
    </collision>
    <!-- for simulation -->
    <inertial>
      <origin rpy="0 0 0" xyz="0 0 0.5"/>
      <mass value="1.0"/>
      <inertia ixx="0.0858" ixy="0.0" ixz="0.0" iyy="0.0858" iyz="0.0" izz="0.005"/>
    </inertial>
    <!-- end for simulation -->
  </link>
  <link name="panda_link2">
    <visual>
      <origin xyz="0 0 0.6" rpy="0 0 0"/>
      <geometry>
        <cylinder length="1.0" radius="0.1"/>
      </geometry>
    </visual>
    <collision>
      <origin xyz="0 0 0.6" rpy="0 0 0"/>
      <geometry>
        <cylinder length="1.0" radius="0.1"/>
      </geometry>
    </collision>
    <!-- for simulation -->
    <inertial>
      <origin rpy="0 0 0" xyz="0 0 0.5"/>
      <mass value="1.0"/>
      <inertia ixx="0.0858" ixy="0.0" ixz="0.0" iyy="0.0858" iyz="0.0" izz="0.005"/>
    </inertial>
    <!-- end for simulation -->
  </link>
  <joint name="panda_joint1" type="revolute">
    <safety_controller k_position="100.0" k_velocity="40.0" soft_lower_limit="-2.8973" soft_upper_limit="2.8973"/>
    <origin rpy="0 0 0" xyz="0 0 0.0"/>
    <parent link="panda_link0"/>
    <child link="panda_link1"/>
    <axis xyz="1 0 0"/>
    <limit effort="87" lower="-2.8973" upper="2.8973" velocity="2.1750"/>
    <!-- for simulation -->
    <dynamics damping="0.0" friction="0.0"/>
    <!-- end for simulation -->
  </joint>
  <joint name="panda_joint2" type="revolute">
    <safety_controller k_position="100.0" k_velocity="40.0" soft_lower_limit="-2.8973" soft_upper_limit="2.8973"/>
    <origin rpy="0 0 0" xyz="0 0 1.1"/>
    <parent link="panda_link1"/>
    <child link="panda_link2"/>
    <axis xyz="1 0 0"/>
    <limit effort="87" lower="-2.8973" upper="2.8973" velocity="2.1750"/>
    <!-- for simulation -->
    <dynamics damping="0.0" friction="0.0"/>
    <!-- end for simulation -->
  </joint>
  <link name="panda_link4">
    <visual>
      <origin xyz="0 0 0.005" rpy="0 0 0"/>
      <geometry>
        <sphere radius="0.1"/>
      </geometry>
    </visual>
    <collision>
      <geometry>
        <sphere radius="0.1"/>
      </geometry>
    </collision>
    <!-- for simulation -->
    <inertial>
      <origin rpy="0 0 0" xyz="0 0 0.005"/>
      <mass value="0.0001"/>
      <inertia ixx="0.00005" ixy="0.0" ixz="0.0" iyy="0.00005" iyz="0.0" izz="0.00005"/>
    </inertial>
    <!-- end for simulation -->
  </link>
  <joint name="panda_joint4" type="fixed">
    <origin rpy="0 0 0" xyz="0 0 1.2"/>
    <parent link="panda_link2"/>
    <child link="panda_link4"/>
    <axis xyz="1 0 0"/>
  </joint>
  <!-- end for simulation -->
</robot>
