<?xml version="1.0"?>
<!-- =================================================================================== -->
<!-- |    This document was autogenerated by xacro from tiago_dual_115.urdf.xacro      | -->
<!-- |    EDITING THIS FILE BY HAND IS NOT RECOMMENDED                                 | -->
<!-- =================================================================================== -->
<!--
  Copyright (c) 2019, PAL Robotics, S.L.
  All rights reserved.

  This work is licensed under the Creative Commons Attribution-NonCommercial-NoDerivs 3.0 Unported License.
  To view a copy of this license, visit http://creativecommons.org/licenses/by-nc-nd/3.0/ or send a letter to
  Creative Commons, 444 Castro Street, Suite 900, Mountain View, California, 94041, USA.
-->
<robot name="tiago_dual">
  <material name="Blue">
    <color rgba="0.0 0.0 0.8 1.0"/>
  </material>
  <material name="Green">
    <color rgba="0.0 0.8 0.0 1.0"/>
  </material>
  <material name="Grey">
    <color rgba="0.7 0.7 0.7 1.0"/>
  </material>
  <material name="LightGrey">
    <color rgba="0.9 0.9 0.9 1.0"/>
  </material>
  <material name="DarkGrey">
    <color rgba="0.1 0.1 0.1 1.0"/>
  </material>
  <material name="Red">
    <color rgba="0.8 0.0 0.0 1.0"/>
  </material>
  <material name="White">
    <color rgba="1.0 1.0 1.0 1.0"/>
  </material>
  <material name="Yellow">
    <color rgba="0.96 0.88 0.14 1.0"/>
  </material>
  <link name="base_laser_link" type="laser">
    <inertial>
      <origin rpy="0 0 0" xyz="-0.02559000000 -0.00056000000 -0.05732000000"/>
      <mass value="0.28922000000"/>
      <inertia ixx="0.00002628919" ixy="0.00000024298" ixz="-0.00000368129" iyy="0.00003374542" iyz="-0.00000001330" izz="0.00005832599"/>
    </inertial>
    <visual>
      <origin rpy="0 0 0" xyz="0 0 0"/>
      <geometry>
        <mesh filename="pmb2_description/meshes/sensors/sick_tim551.stl"/>
      </geometry>
      <material name="DarkGrey"/>
    </visual>
  </link>
  <joint name="base_laser_joint" type="fixed">
    <axis xyz="0 1 0"/>
    <origin rpy="0 0 0" xyz="0.202 0.0 -0.004"/>
    <parent link="base_link"/>
    <child link="base_laser_link"/>
  </joint>
  <!-- Base -->
  <link name="base_link">
    <inertial>
      <origin rpy="0 0 0" xyz="-0.00000106 0.00000109 0.0000387"/>
      <mass value="28.26649"/>
      <inertia ixx="0.465408937" ixy="0.002160024" ixz="-0.001760255" iyy="0.483193291" iyz="-0.000655952" izz="0.550939703"/>
    </inertial>
    <visual>
      <origin rpy="0 0 0" xyz="0 0 0"/>
      <geometry>
        <mesh filename="pmb2_description/meshes/base/base.stl"/>
      </geometry>
      <material name="White"/>
    </visual>
    <collision>
      <origin rpy="0 0 0" xyz="0 0 0"/>
      <geometry>
        <mesh filename="pmb2_description/meshes/base/base_collision.stl"/>
      </geometry>
      <material name="White"/>
    </collision>
  </link>
  <!-- Base footprint -->
  <!--
  <link name="base_footprint"/>
  <joint name="base_footprint_joint" type="fixed">
    <origin rpy="0 0 0" xyz="0 0 0.0985"/>
    <child link="base_link"/>
    <parent link="base_footprint"/>
  </joint>
  -->
  <link name="base_cover_link">
    <inertial>
      <origin rpy="0 0 0" xyz="0.22414000000 0.00002000000 0.04681000000"/>
      <mass value="0.25821000000"/>
      <inertia ixx="0.00023719188" ixy="0.00000006119" ixz="-0.00000011799" iyy="0.00028335052" iyz="0.00000000774" izz="0.00038497063"/>
    </inertial>
    <visual>
      <origin rpy="0 0 0" xyz="0 0 0"/>
      <geometry>
        <mesh filename="pmb2_description/meshes/base/base_ring.stl"/>
      </geometry>
      <material name="Orange"/>
    </visual>
  </link>
  <joint name="cover_joint" type="fixed">
    <parent link="base_link"/>
    <child link="base_cover_link"/>
    <origin rpy="0 0 0" xyz="0 0 0.0315"/>
    <!--origin rpy="0 0 0" xyz="0 0 0.13"/-->
  </joint>
  <link name="base_antenna_left_link">
    <inertial>
      <origin rpy="0 0 0" xyz="0 0 0"/>
      <mass value="0.000001"/>
      <inertia ixx="0.00000002371" ixy="0.00000006119" ixz="0.00000001179" iyy="0.00000002833" iyz="0.00000000774" izz="0.00000003849"/>
    </inertial>
    <visual>
      <origin rpy="0 0 0" xyz="0 0 0"/>
      <geometry>
        <mesh filename="pmb2_description/meshes/objects/antenna.stl"/>
      </geometry>
      <material name="Black"/>
    </visual>
    <collision>
      <origin rpy="0 0 0" xyz="0 0 0.085"/>
      <geometry>
        <cylinder length="0.17" radius="0.005"/>
      </geometry>
      <material name="Black"/>
    </collision>
  </link>
  <joint name="base_antenna_left_joint" type="fixed">
    <parent link="base_link"/>
    <child link="base_antenna_left_link"/>
    <origin rpy="0 0 0" xyz="-0.201 0.1062 0.195"/>
  </joint>
  <link name="base_antenna_right_link">
    <inertial>
      <origin rpy="0 0 0" xyz="0 0 0"/>
      <mass value="0.000001"/>
      <inertia ixx="0.00000002371" ixy="0.00000006119" ixz="0.00000001179" iyy="0.00000002833" iyz="0.00000000774" izz="0.00000003849"/>
    </inertial>
    <visual>
      <origin rpy="0 0 0" xyz="0 0 0"/>
      <geometry>
        <mesh filename="pmb2_description/meshes/objects/antenna.stl"/>
      </geometry>
      <material name="Black"/>
    </visual>
    <collision>
      <origin rpy="0 0 0" xyz="0 0 0.085"/>
      <geometry>
        <cylinder length="0.17" radius="0.005"/>
      </geometry>
      <material name="Black"/>
    </collision>
  </link>
  <joint name="base_antenna_right_joint" type="fixed">
    <parent link="base_link"/>
    <child link="base_antenna_right_link"/>
    <origin rpy="0 0 0" xyz="-0.201 -0.1062 0.195"/>
  </joint>
  <link name="base_imu_link">
    <inertial>
      <mass value="0.01"/>
      <origin xyz="0 0 0"/>
      <inertia ixx="0.000001" ixy="0" ixz="0" iyy="0.000001" iyz="0" izz="0.000001"/>
    </inertial>
    <!--visual>
        <origin rpy="0 0 0" xyz="0 0 0"/>
        <geometry>
          <box size="0.01 0.01 0.01"/>
        </geometry>
      </visual-->
  </link>
  <joint name="base_imu_joint" type="fixed">
    <parent link="base_link"/>
    <child link="base_imu_link"/>
    <origin rpy="0 0 -1.57079632679" xyz="0.10171 0 0.11282"/>
  </joint>
  <link name="wheel_right_link">
    <inertial>
      <origin rpy="0 0 0" xyz="0 0 -0.00207"/>
      <mass value="100"/>
      <inertia ixx="0.00499743171" ixy="4.464e-08" ixz="-0.00000002245" iyy="0.00499741733" iyz="-1.64e-09" izz="0.00839239692"/>
    </inertial>
    <visual>
      <origin rpy="-0.0 0 0" xyz="0 0 0"/>
      <geometry>
        <!--cylinder length="0.05" radius="0.1"/-->
        <mesh filename="pmb2_description/meshes/wheels/wheel.stl"/>
      </geometry>
      <material name="DarkGrey"/>
    </visual>
    <collision>
      <origin rpy="0 0 0" xyz="0 0 0"/>
      <geometry>
        <cylinder length="0.05" radius="0.1"/>
        <!--sphere radius="0.0985"/-->
      </geometry>
    </collision>
  </link>
  <link name="suspension_right_link">
    <inertial>
      <origin rpy="0 0 0" xyz="0 0 -0.02"/>
      <mass value="10"/>
      <inertia ixx="1.0" ixy="0" ixz="0" iyy="1.0" iyz="0" izz="1.0"/>
    </inertial>
    <kinematic>0</kinematic>
    <gravity>1</gravity>
  </link>
  <joint name="suspension_right_joint" type="prismatic">
    <origin rpy="0 0 0" xyz="0 0 0"/>
    <axis xyz="0 0 1"/>
    <limit effort="100.0" lower="-0.005" upper="0.005" velocity="1.0"/>
    <child link="suspension_right_link"/>
    <parent link="base_link"/>
    <calibration rising="0.0"/>
    <dynamics damping="100"/>
    <safety_controller k_position="0" k_velocity="10" soft_lower_limit="-0.005" soft_upper_limit="0.005"/>
  </joint>
  <joint name="wheel_right_joint" type="continuous">
    <parent link="suspension_right_link"/>
    <child link="wheel_right_link"/>
    <origin rpy="-1.57079632679 0 0" xyz="0 -0.2022 0.0"/>
    <axis xyz="0 0 1"/>
    <limit effort="1000.0" velocity="10000"/>
  </joint>
  <link name="wheel_left_link">
    <inertial>
      <origin rpy="0 0 0" xyz="0 0 0.00207"/>
      <mass value="100"/>
      <inertia ixx="0.00499743171" ixy="-4.464e-08" ixz="-0.00000002245" iyy="0.00499741733" iyz="1.64e-09" izz="0.00839239692"/>
    </inertial>
    <visual>
      <origin rpy="-3.14159265359 0 0" xyz="0 0 0"/>
      <geometry>
        <mesh filename="pmb2_description/meshes/wheels/wheel.stl"/>
        <!--cylinder length="0.05" radius="0.1"/-->
      </geometry>
      <material name="DarkGrey"/>
    </visual>
    <collision>
      <origin rpy="0 0 0" xyz="0 0 0"/>
      <geometry>
        <cylinder length="0.05" radius="0.1"/>
        <!--sphere radius="0.0985"/-->
        <!-- length="${width}"/> -->
      </geometry>
    </collision>
  </link>
  <link name="suspension_left_link">
    <inertial>
      <origin rpy="0 0 0" xyz="0 0 -0.02"/>
      <mass value="10"/>
      <inertia ixx="1.0" ixy="0" ixz="0" iyy="1.0" iyz="0" izz="1.0"/>
    </inertial>
    <kinematic>0</kinematic>
    <gravity>1</gravity>
  </link>
  <joint name="suspension_left_joint" type="prismatic">
    <origin rpy="0 0 0" xyz="0 0 0"/>
    <axis xyz="0 0 1"/>
    <limit effort="100.0" lower="-0.005" upper="0.005" velocity="1.0"/>
    <child link="suspension_left_link"/>
    <parent link="base_link"/>
    <calibration rising="0.0"/>
    <dynamics damping="100"/>
    <safety_controller k_position="0" k_velocity="10" soft_lower_limit="-0.005" soft_upper_limit="0.005"/>
  </joint>
  <joint name="wheel_left_joint" type="continuous">
    <parent link="suspension_left_link"/>
    <child link="wheel_left_link"/>
    <origin rpy="-1.57079632679 0 0" xyz="0 0.2022 0.0"/>
    <axis xyz="0 0 1"/>
    <limit effort="10000.0" velocity="10000"/>
  </joint>
  <link name="caster_front_right_1_link">
    <inertial>
      <origin rpy="0 0 0" xyz="-0.00634599 0.00005347 -0.02037519"/>
      <mass value="0.05144761"/>
      <inertia ixx="0.00001513" ixy="-0.00000003" ixz="0.00000267" iyy="0.00001309" iyz="-0.00000005" izz="0.00001198"/>
    </inertial>
    <visual>
      <origin rpy="0 0 0" xyz="0 0 0"/>
      <geometry>
        <mesh filename="pmb2_description/meshes/wheels/caster_1.stl"/>
      </geometry>
      <material name="Grey"/>
    </visual>
  </link>
  <link name="caster_front_right_2_link">
    <inertial>
      <origin rpy="0 0 0" xyz="0 0 0"/>
      <mass value="0.08855784"/>
      <inertia ixx="0.00001075" ixy="0" ixz="0" iyy="0.00001541" iyz="0" izz="0.00001075"/>
    </inertial>
    <visual>
      <origin rpy="0 0 0" xyz="0 0 0"/>
      <geometry>
        <mesh filename="pmb2_description/meshes/wheels/caster_2.stl"/>
      </geometry>
      <material name="DarkGrey"/>
    </visual>
    <collision>
      <origin rpy="0 0 0" xyz="0 0 0"/>
      <geometry>
        <!--sphere radius="0.025"/-->
        <cylinder length="0.001" radius="0.025"/>
      </geometry>
    </collision>
  </link>
  <joint name="caster_front_right_1_joint" type="fixed">
    <parent link="base_link"/>
    <child link="caster_front_right_1_link"/>
    <origin rpy="0 0 0" xyz="0.1695 -0.102 -0.0335"/>
    <axis xyz="0 0 1"/>
    <dynamics damping="0.005" friction="0.0"/>
  </joint>
  <joint name="caster_front_right_2_joint" type="continuous">
    <parent link="caster_front_right_1_link"/>
    <child link="caster_front_right_2_link"/>
    <origin rpy="-1.57079632679 0 0" xyz="-0.016 0.0000 -0.040"/>
    <axis xyz="0 0 1"/>
  </joint>
  <link name="caster_front_left_1_link">
    <inertial>
      <origin rpy="0 0 0" xyz="-0.00634599 0.00005347 -0.02037519"/>
      <mass value="0.05144761"/>
      <inertia ixx="0.00001513" ixy="-0.00000003" ixz="0.00000267" iyy="0.00001309" iyz="-0.00000005" izz="0.00001198"/>
    </inertial>
    <visual>
      <origin rpy="0 0 0" xyz="0 0 0"/>
      <geometry>
        <mesh filename="pmb2_description/meshes/wheels/caster_1.stl"/>
      </geometry>
      <material name="Grey"/>
    </visual>
  </link>
  <link name="caster_front_left_2_link">
    <inertial>
      <origin rpy="0 0 0" xyz="0 0 0"/>
      <mass value="0.08855784"/>
      <inertia ixx="0.00001075" ixy="0" ixz="0" iyy="0.00001541" iyz="0" izz="0.00001075"/>
    </inertial>
    <visual>
      <origin rpy="0 0 0" xyz="0 0 0"/>
      <geometry>
        <mesh filename="pmb2_description/meshes/wheels/caster_2.stl"/>
      </geometry>
      <material name="DarkGrey"/>
    </visual>
    <collision>
      <origin rpy="0 0 0" xyz="0 0 0"/>
      <geometry>
        <!--sphere radius="0.025"/-->
        <cylinder length="0.001" radius="0.025"/>
      </geometry>
    </collision>
  </link>
  <joint name="caster_front_left_1_joint" type="fixed">
    <parent link="base_link"/>
    <child link="caster_front_left_1_link"/>
    <origin rpy="0 0 0" xyz="0.1695 0.102 -0.0335"/>
    <axis xyz="0 0 1"/>
    <dynamics damping="0.005" friction="0.0"/>
  </joint>
  <joint name="caster_front_left_2_joint" type="continuous">
    <parent link="caster_front_left_1_link"/>
    <child link="caster_front_left_2_link"/>
    <origin rpy="-1.57079632679 0 0" xyz="-0.016 0.0000 -0.040"/>
    <axis xyz="0 0 1"/>
  </joint>
  <link name="caster_back_right_1_link">
    <inertial>
      <origin rpy="0 0 0" xyz="-0.00634599 0.00005347 -0.02037519"/>
      <mass value="0.05144761"/>
      <inertia ixx="0.00001513" ixy="-0.00000003" ixz="0.00000267" iyy="0.00001309" iyz="-0.00000005" izz="0.00001198"/>
    </inertial>
    <visual>
      <origin rpy="0 0 0" xyz="0 0 0"/>
      <geometry>
        <mesh filename="pmb2_description/meshes/wheels/caster_1.stl"/>
      </geometry>
      <material name="Grey"/>
    </visual>
  </link>
  <link name="caster_back_right_2_link">
    <inertial>
      <origin rpy="0 0 0" xyz="0 0 0"/>
      <mass value="0.08855784"/>
      <inertia ixx="0.00001075" ixy="0" ixz="0" iyy="0.00001541" iyz="0" izz="0.00001075"/>
    </inertial>
    <visual>
      <origin rpy="0 0 0" xyz="0 0 0"/>
      <geometry>
        <mesh filename="pmb2_description/meshes/wheels/caster_2.stl"/>
      </geometry>
      <material name="DarkGrey"/>
    </visual>
    <collision>
      <origin rpy="0 0 0" xyz="0 0 0"/>
      <geometry>
        <!--sphere radius="0.025"/-->
        <cylinder length="0.001" radius="0.025"/>
      </geometry>
    </collision>
  </link>
  <joint name="caster_back_right_1_joint" type="fixed">
    <parent link="base_link"/>
    <child link="caster_back_right_1_link"/>
    <origin rpy="0 0 0" xyz="-0.1735 -0.102 -0.0335"/>
    <axis xyz="0 0 1"/>
    <dynamics damping="0.005" friction="0.0"/>
  </joint>
  <joint name="caster_back_right_2_joint" type="continuous">
    <parent link="caster_back_right_1_link"/>
    <child link="caster_back_right_2_link"/>
    <origin rpy="-1.57079632679 0 0" xyz="-0.016 0.0000 -0.040"/>
    <axis xyz="0 0 1"/>
  </joint>
  <link name="caster_back_left_1_link">
    <inertial>
      <origin rpy="0 0 0" xyz="-0.00634599 0.00005347 -0.02037519"/>
      <mass value="0.05144761"/>
      <inertia ixx="0.00001513" ixy="-0.00000003" ixz="0.00000267" iyy="0.00001309" iyz="-0.00000005" izz="0.00001198"/>
    </inertial>
    <visual>
      <origin rpy="0 0 0" xyz="0 0 0"/>
      <geometry>
        <mesh filename="pmb2_description/meshes/wheels/caster_1.stl"/>
      </geometry>
      <material name="Grey"/>
    </visual>
  </link>
  <link name="caster_back_left_2_link">
    <inertial>
      <origin rpy="0 0 0" xyz="0 0 0"/>
      <mass value="0.08855784"/>
      <inertia ixx="0.00001075" ixy="0" ixz="0" iyy="0.00001541" iyz="0" izz="0.00001075"/>
    </inertial>
    <visual>
      <origin rpy="0 0 0" xyz="0 0 0"/>
      <geometry>
        <mesh filename="pmb2_description/meshes/wheels/caster_2.stl"/>
      </geometry>
      <material name="DarkGrey"/>
    </visual>
    <collision>
      <origin rpy="0 0 0" xyz="0 0 0"/>
      <geometry>
        <!--sphere radius="0.025"/-->
        <cylinder length="0.001" radius="0.025"/>
      </geometry>
    </collision>
  </link>
  <joint name="caster_back_left_1_joint" type="fixed">
    <parent link="base_link"/>
    <child link="caster_back_left_1_link"/>
    <origin rpy="0 0 0" xyz="-0.1735 0.102 -0.0335"/>
    <axis xyz="0 0 1"/>
    <dynamics damping="0.005" friction="0.0"/>
  </joint>
  <joint name="caster_back_left_2_joint" type="continuous">
    <parent link="caster_back_left_1_link"/>
    <child link="caster_back_left_2_link"/>
    <origin rpy="-1.57079632679 0 0" xyz="-0.016 0.0000 -0.040"/>
    <axis xyz="0 0 1"/>
  </joint>
  <!-- Bottom fixed part of column -->
  <link name="torso_fixed_link">
    <inertial>
      <origin rpy="0.00000 0.00000 0.00000" xyz="0.02435 -0.00464 0.15900"/>
      <mass value="14.01360"/>
      <inertia ixx="0.38341100000" ixy="0.00036400000" ixz="-0.02438900000" iyy="0.40577300000" iyz="-0.00078200000" izz="0.07699800000"/>
    </inertial>
    <visual>
      <origin rpy="0 0 0" xyz="0 0 0"/>
      <geometry>
        <mesh filename="tiago_dual_description/meshes/torso/torso_fix.stl" scale="1 1 1"/>
      </geometry>
      <material name="LightGrey"/>
    </visual>
    <collision>
      <origin rpy="0 0 0" xyz="0.085 0.0 0.02"/>
      <geometry>
        <box size="0.4 0.25 0.04"/>
      </geometry>
    </collision>
    <collision>
      <origin rpy="0 0 0" xyz="0 0 0.05"/>
      <geometry>
        <box size="0.25 0.25 0.1"/>
      </geometry>
    </collision>
  </link>
  <joint name="torso_fixed_joint" type="fixed">
    <origin rpy="0 0 0" xyz="-0.062 0.0 0.193"/>
    <parent link="base_link"/>
    <child link="torso_fixed_link"/>
    <axis xyz="0 0 0"/>
  </joint>
  <!-- Middle extending  -->
  <link name="torso_fixed_column_link">
    <inertial>
      <origin rpy="0 0 0" xyz="0 0 0"/>
      <mass value="0.01"/>
      <inertia ixx="0.000001" ixy="0" ixz="0" iyy="0.000001" iyz="0" izz="0.000001"/>
    </inertial>
    <visual>
      <origin rpy="0 0 0" xyz="0 0 0.275"/>
      <geometry>
        <box size="0.18 0.2 0.55"/>
      </geometry>
      <material name="DarkGrey"/>
    </visual>
    <collision>
      <origin rpy="0 0 0" xyz="0 0 0.275"/>
      <geometry>
        <box size="0.23 0.23 0.55"/>
      </geometry>
      <material name="DarkGrey"/>
    </collision>
  </link>
  <joint name="torso_fixed_column_joint" type="fixed">
    <origin rpy="0 0 0" xyz="-0.062 0 0.195"/>
    <parent link="base_link"/>
    <child link="torso_fixed_column_link"/>
    <axis xyz="0 0 0"/>
  </joint>
  <link name="torso_lift_link">
    <inertial>
      <origin rpy="0.00000 0.00000 0.00000" xyz="0.04361 -0.00116 -0.17334"/>
      <mass value="9.594213"/>
      <inertia ixx="0.326395" ixy="-0.000844" ixz="-0.018905" iyy="0.235332" iyz="0.009042" izz="0.176168"/>
    </inertial>
    <visual>
      <origin rpy="0 0 0" xyz="0 0 0"/>
      <geometry>
        <mesh filename="tiago_dual_description/meshes/torso/torso_lift_dual_arm.stl" scale="1 1 1"/>
      </geometry>
      <material name="White"/>
    </visual>
    <collision>
      <origin rpy="0 0 0" xyz="0 0 0"/>
      <geometry>
        <mesh filename="tiago_description/meshes/torso/torso_lift_collision_core.dae" scale="1 1 1"/>
      </geometry>
      <material name="LightGrey"/>
    </collision>
    <!-- left shoulder collision-->
    <collision>
      <origin rpy="0 0 0" xyz="-0.131 0.17 -0.02556"/>
      <geometry>
        <mesh filename="tiago_description/meshes/torso/torso_lift_collision_shoulder.dae" scale="1 1 1"/>
      </geometry>
      <material name="LightGrey"/>
    </collision>
    <!-- right shoulder collision-->
    <collision>
      <origin rpy="0 0 0" xyz="-0.131 -0.19 -0.02556"/>
      <geometry>
        <mesh filename="tiago_description/meshes/torso/torso_lift_collision_shoulder.dae" scale="1 1 1"/>
      </geometry>
      <material name="LightGrey"/>
    </collision>
    <collision>
      <origin rpy="0 0 0" xyz="0 0 0"/>
      <geometry>
        <mesh filename="tiago_description/meshes/torso/torso_lift_collision_neck.dae" scale="1 1 1"/>
      </geometry>
      <material name="LightGrey"/>
    </collision>
  </link>
  <joint name="torso_lift_joint" type="prismatic">
    <origin rpy="0.0 0.0 0.0" xyz="0.0 0.0 0.597"/>
    <parent link="torso_fixed_link"/>
    <child link="torso_lift_link"/>
    <axis xyz="0 0 1"/>
    <limit effort="2000" lower="0" upper="0.35" velocity="0.35"/>
    <calibration rising="0.0"/>
    <dynamics damping="1000"/>
    <safety_controller k_position="20" k_velocity="20" soft_lower_limit="0.0" soft_upper_limit="0.35"/>
  </joint>
  <link name="head_1_link">
    <inertial>
      <origin rpy="0.00000 0.00000 0.00000" xyz="-0.00508 0.00237 0.07229"/>
      <mass value="0.62220"/>
      <inertia ixx="0.00119200000" ixy="-0.00000700000" ixz="0.00009600000" iyy="0.00140200000" iyz="0.00000400000" izz="0.00088900000"/>
    </inertial>
    <visual>
      <origin rpy="0 0 0" xyz="0 0 0"/>
      <geometry>
        <mesh filename="tiago_description/meshes/head/head_1.stl" scale="1 1 1"/>
      </geometry>
      <material name="White"/>
    </visual>
    <collision>
      <origin rpy="0 0 0.0" xyz="0.0 0 0"/>
      <geometry>
        <mesh filename="tiago_description/meshes/head/head_1_collision.dae" scale="1 1 1"/>
      </geometry>
      <material name="White"/>
    </collision>
  </link>
  <joint name="head_1_joint" type="revolute">
    <parent link="torso_lift_link"/>
    <child link="head_1_link"/>
    <origin rpy="0 0 0" xyz="0.182 0.0 0.0"/>
    <axis xyz="0 0 1"/>
    <limit effort="5.197" lower="-1.308996939" upper="1.308996939" velocity="3.0"/>
    <dynamics damping="0.5" friction="1.0"/>
    <safety_controller k_position="20" k_velocity="20" soft_lower_limit="-1.238996939" soft_upper_limit="1.238996939"/>
  </joint>
  <link name="head_2_link">
    <inertial>
      <origin rpy="0.00000 0.00000 0.00000" xyz="0.04700 0.05542 0.00022"/>
      <mass value="0.66123"/>
      <inertia ixx="0.00462000000" ixy="0.00068900000" ixz="0.00000600000" iyy="0.00486100000" iyz="0.00000600000" izz="0.00313200000"/>
    </inertial>
    <visual>
      <origin rpy="0 0 0" xyz="0 0 0"/>
      <geometry>
        <mesh filename="tiago_description/meshes/head/head_2.stl" scale="1 1 1"/>
      </geometry>
      <material name="White"/>
    </visual>
    <collision>
      <origin rpy="0 0 0" xyz="0 0 0"/>
      <geometry>
        <mesh filename="tiago_description/meshes/head/head_2_collision.dae" scale="1 1 1"/>
      </geometry>
    </collision>
  </link>
  <joint name="head_2_joint" type="revolute">
    <parent link="head_1_link"/>
    <child link="head_2_link"/>
    <origin rpy="1.57079632679 0 0" xyz="0.005 0.0 0.098"/>
    <axis xyz="0 0 1"/>
    <limit effort="2.77" lower="-1.0471975512" upper="0.785398163397" velocity="3.0"/>
    <dynamics damping="0.5" friction="1.0"/>
    <safety_controller k_position="20" k_velocity="20" soft_lower_limit="-0.977197551197" soft_upper_limit="0.715398163397"/>
  </joint>
  <!-- frames in the center of the camera -->
  <joint name="xtion_joint" type="fixed">
    <origin rpy="-1.57079632679 0.0 0.0" xyz="0.0908 0.08 0.0"/>
    <parent link="head_2_link"/>
    <child link="xtion_link"/>
  </joint>
  <link name="xtion_link">
    <inertial>
      <origin rpy="0 0 0" xyz="-0.00936000000 -0.00003000000 -0.00273000000"/>
      <mass value="0.21970000000"/>
      <inertia ixx="0.00000429247" ixy="0.00000000000" ixz="0.00000002565" iyy="0.00000008027" iyz="0.00000000000" izz="0.00000427339"/>
    </inertial>
      <visual>
        <origin xyz="0 0 0" rpy="0 0 0"/>
        <geometry>
          <mesh filename="tiago_description/meshes/sensors/xtion_pro_live/xtion_pro_live.dae" />
        </geometry>
        <material name="Grey">
          <color rgba="0.5 0.5 0.5 1"/>
        </material>
      </visual>
      <collision>
        <origin xyz="-0.01 0.0025 0" rpy="0 0 0"/>
        <geometry>
          <box size="0.04 0.185 0.03"/>
        </geometry>
      </collision>
  </link>
  <!--************************-->
  <!--        SHOULDER        -->
  <!--************************-->
  <link name="arm_left_1_link">
    <inertial>
      <!--<origin xyz="0.061191 ${reflect * -0.022397} -0.012835" rpy="0.00000 0.00000 0.00000"/>-->
      <origin rpy="0.00000 0.00000 0.00000" xyz="0.061191 -0.022397 0.012835"/>
      <mass value="1.563428"/>
      <inertia ixx="0.002471" ixy="0.001809" ixz="-0.001202" iyy="0.006132" iyz="-0.000494" izz="0.006704"/>
    </inertial>
    <!-- M90 module -->
    <visual>
      <origin rpy="0 0 0" xyz="0 0 0"/>
      <geometry>
        <mesh filename="tiago_description/meshes/arm/arm_1.stl" scale="1 -1 -1"/>
      </geometry>
      <material name="White"/>
    </visual>
    <collision>
      <origin rpy="0 0 0" xyz="0 0 0"/>
      <geometry>
        <mesh filename="tiago_description/meshes/arm/arm_1_collision.dae" scale="1 -1 -1"/>
      </geometry>
    </collision>
  </link>
  <joint name="arm_left_1_joint" type="revolute">
    <parent link="torso_lift_link"/>
    <child link="arm_left_1_link"/>
    <origin rpy="3.14159265359 0 1.57079632679" xyz="0.02556 0.19 -0.171"/>
    <axis xyz="0 0 1"/>
    <limit effort="43.0" lower="-1.1780972451" upper="1.57079632679" velocity="1.95"/>
    <dynamics damping="1.0" friction="1.0"/>
    <safety_controller k_position="20" k_velocity="20" soft_lower_limit="-1.1080972451" soft_upper_limit="1.50079632679"/>
  </joint>
  <link name="arm_left_2_link">
    <inertial>
      <origin rpy="0.00000 0.00000 0.00000" xyz="0.030432 0.000229 0.005942"/>
      <mass value="1.800397"/>
      <inertia ixx="0.001809" ixy="-1.5e-05" ixz="-0.000254" iyy="0.004333" iyz="-1.4e-05" izz="0.004341"/>
    </inertial>
    <visual>
      <!-- <origin xyz="0 0 0" rpy="${180 * deg_to_rad} ${0 * deg_to_rad} ${-90 * deg_to_rad}" /> -->
      <origin rpy="0.0 0.0 0.0" xyz="0 0 0"/>
      <geometry>
        <mesh filename="tiago_description/meshes/arm/arm_2.stl" scale="1 1 -1"/>
      </geometry>
      <material name="DarkGrey"/>
    </visual>
    <collision>
      <!-- <origin xyz="0 0 0" rpy="${180 * deg_to_rad} ${0 * deg_to_rad} ${-90 * deg_to_rad}" /> -->
      <origin rpy="0.0 0.0 0.0" xyz="0 0 0"/>
      <geometry>
        <mesh filename="tiago_description/meshes/arm/arm_2_collision.dae" scale="1 1 -1"/>
      </geometry>
    </collision>
  </link>
  <joint name="arm_left_2_joint" type="revolute">
    <parent link="arm_left_1_link"/>
    <child link="arm_left_2_link"/>
    <origin rpy="1.57079632679 0.0 0.0" xyz="0.125 -0.0195 0.031"/>
    <axis xyz="0 0 1"/>
    <limit effort="43.0" lower="-1.1780972451" upper="1.57079632679" velocity="1.95"/>
    <dynamics damping="1.0" friction="1.0"/>
    <safety_controller k_position="20" k_velocity="20" soft_lower_limit="-1.1080972451" soft_upper_limit="1.50079632679"/>
  </joint>
  <link name="arm_left_3_link">
    <inertial>
      <origin rpy="0.00000 0.00000 0.00000" xyz="0.007418 -0.004361 0.134194"/>
      <mass value="1.8"/>
      <inertia ixx="0.019541" ixy="-0.000105" ixz="-0.001717" iyy="0.019936" iyz="-0.000852" izz="0.002864"/>
    </inertial>
    <visual>
      <origin rpy="0 0 0" xyz="0 0 0"/>
      <geometry>
        <mesh filename="tiago_description/meshes/arm/arm_3.stl" scale="1 1 -1"/>
      </geometry>
      <material name="DarkGrey"/>
    </visual>
    <collision>
      <origin rpy="0 0 0" xyz="0 0 0"/>
      <geometry>
        <mesh filename="tiago_description/meshes/arm/arm_3_collision.dae" scale="1 1 -1"/>
      </geometry>
    </collision>
  </link>
  <joint name="arm_left_3_joint" type="revolute">
    <parent link="arm_left_2_link"/>
    <child link="arm_left_3_link"/>
    <origin rpy="-1.57079632679 3.14159265359 -1.57079632679" xyz="0.0895 0.0 -0.0015"/>
    <axis xyz="0 0 1"/>
    <limit effort="26" lower="-0.785398163397" upper="3.92699081699" velocity="2.35"/>
    <dynamics damping="1.0" friction="1.0"/>
    <safety_controller k_position="20" k_velocity="20" soft_lower_limit="-0.715398163397" soft_upper_limit="3.85699081699"/>
  </joint>
  <!--************************-->
  <!--        ELBOW           -->
  <!--************************-->
  <link name="arm_left_4_link">
    <inertial>
      <origin rpy="0.00000 0.00000 0.00000" xyz="0.095658 -0.014666 -0.018133"/>
      <mass value="1.432697"/>
      <inertia ixx="0.002040" ixy="-0.000725" ixz="0.00115" iyy="0.008424" iyz="-0.000204" izz="0.008686"/>
    </inertial>
    <visual>
      <origin rpy="0 0 0" xyz="0 0 0"/>
      <geometry>
        <mesh filename="tiago_description/meshes/arm/arm_4.stl" scale="-1 -1 -1"/>
      </geometry>
      <material name="DarkGrey"/>
    </visual>
    <collision>
      <origin rpy="0 0 0" xyz="0 0 0"/>
      <geometry>
        <mesh filename="tiago_description/meshes/arm/arm_4_collision.dae" scale="-1 -1 -1"/>
      </geometry>
    </collision>
  </link>
  <joint name="arm_left_4_joint" type="revolute">
    <parent link="arm_left_3_link"/>
    <child link="arm_left_4_link"/>
    <origin rpy="1.57079632679 -1.57079632679 0.0" xyz="-0.02 -0.027 0.222"/>
    <axis xyz="0 0 1"/>
    <limit effort="26" lower="-0.392699081699" upper="2.35619449019" velocity="2.35"/>
    <dynamics damping="1.0" friction="1.0"/>
    <safety_controller k_position="20" k_velocity="20" soft_lower_limit="-0.322699081699" soft_upper_limit="2.28619449019"/>
  </joint>
  <!--************************-->
  <!--        WRIST           -->
  <!--************************-->
  <!--************************-->
  <!--        WRIST           -->
  <!--************************-->
  <link name="arm_left_5_link">
    <inertial>
      <origin rpy="0.00000 0.00000 0.00000" xyz="0.001078 -0.000151 0.077173"/>
      <mass value="1.655819"/>
      <inertia ixx="0.00613800000" ixy="-0.00000400000" ixz="0.00015600000" iyy="0.00564000000" iyz="0.00002200000" izz="0.00179700000"/>
    </inertial>
    <visual>
      <origin rpy="0 3.14 0" xyz="0 0 0"/>
      <geometry>
        <!--mesh filename="tiago_description/meshes/arm/arm_5-wrist-2010.stl" scale="-1 -1 -1"/-->
        <mesh filename="tiago_description/meshes/arm/arm_5-wrist-2010.stl" scale="1 1 1"/>
      </geometry>
      <material name="LightGrey"/>
    </visual>
    <collision>
      <origin rpy="0 0 0" xyz="0 0 0"/>
      <geometry>
        <mesh filename="tiago_description/meshes/arm/arm_5_collision-wrist-2010.dae" scale="-1 -1 -1"/>
      </geometry>
    </collision>
  </link>
  <joint name="arm_left_5_joint" type="revolute">
    <parent link="arm_left_4_link"/>
    <child link="arm_left_5_link"/>
    <origin rpy="1.57079632679 -1.57079632679 -1.57079632679" xyz="0.162 -0.02 -0.027"/>
    <axis xyz="0 0 1"/>
    <limit effort="3" lower="-2.09439510239" upper="2.09439510239" velocity="1.95"/>
    <dynamics damping="1.0" friction="1.0"/>
    <safety_controller k_position="20" k_velocity="20" soft_lower_limit="-2.07439510239" soft_upper_limit="2.07439510239"/>
  </joint>
  <link name="arm_left_6_link">
    <inertial>
      <origin rpy="0.00000 0.00000 0.00000" xyz="-0.000153 -0.003122 0.000183"/>
      <mass value="0.370063"/>
      <inertia ixx="0.00021500000" ixy="0.00000000000" ixz="0.00000000000" iyy="0.00017000000" iyz="0.00000200000" izz="0.00017400000"/>
    </inertial>
    <visual>
      <origin rpy="0 0 0" xyz="0 0 0"/>
      <geometry>
        <mesh filename="tiago_description/meshes/arm/arm_6-wrist-2010.stl" scale="-1 1 1"/>
      </geometry>
      <material name="LightGrey"/>
    </visual>
    <collision>
      <origin rpy="0 0 0" xyz="0 0 0"/>
      <geometry>
        <mesh filename="tiago_description/meshes/arm/arm_6_collision-wrist-2010.dae" scale="-1 1 1"/>
      </geometry>
    </collision>
  </link>
  <joint name="arm_left_6_joint" type="revolute">
    <parent link="arm_left_5_link"/>
    <child link="arm_left_6_link"/>
    <origin rpy="0.0 -1.57079632679 -1.57079632679" xyz="0 0 -0.15"/>
    <axis xyz="0 0 1"/>
    <limit effort="6.6" lower="-1.41371669412" upper="1.41371669412" velocity="1.76"/>
    <dynamics damping="1.0" friction="1.0"/>
    <safety_controller k_position="20" k_velocity="20" soft_lower_limit="-1.39371669412" soft_upper_limit="1.39371669412"/>
  </joint>
  <link name="arm_left_7_link">
    <inertial>
      <origin rpy="0.00000 0.00000 0.00000" xyz="0.000010 -0.000003 -0.007774"/>
      <mass value="0.234252"/>
      <inertia ixx="0.00014200000" ixy="0.00000000000" ixz="0.00000000000" iyy="0.00011300000" iyz="0.00000000000" izz="0.00005200000"/>
    </inertial>
  </link>
  <joint name="arm_left_7_joint" type="revolute">
    <parent link="arm_left_6_link"/>
    <child link="arm_left_7_link"/>
    <origin rpy="1.57079632679 0.0 1.57079632679" xyz="0 0 0"/>
    <axis xyz="0 0 1"/>
    <limit effort="6.6" lower="-2.09439510239" upper="2.09439510239" velocity="1.76"/>
    <dynamics damping="1.0" friction="1.0"/>
    <safety_controller k_position="20" k_velocity="20" soft_lower_limit="-2.07439510239" soft_upper_limit="2.07439510239"/>
  </joint>
  <!--***********************-->
  <!--        TOOL           -->
  <!--***********************-->
  <link name="arm_left_tool_link">
    <inertial>
      <mass value="0.1"/>
      <inertia ixx="8.33E-07" ixy="0.0" ixz="0.0" iyy="8.33E-07" iyz="0.0" izz="1.25E-06"/>
    </inertial>
    <visual>
      <origin rpy="0 1.57079632679 0" xyz="0.001 0 0"/>
      <geometry>
        <cylinder length="0.005" radius="0.005"/>
      </geometry>
      <material name="LightGrey"/>
    </visual>
    <collision>
      <origin rpy="0 1.57079632679 0" xyz="0.001 0 0"/>
      <geometry>
        <cylinder length="0.005" radius="0.005"/>
      </geometry>
    </collision>
  </link>
  <joint name="arm_left_tool_joint" type="fixed">
    <parent link="arm_left_7_link"/>
    <child link="arm_left_tool_link"/>
    <origin rpy="1.57079632679 1.57079632679 3.14159265359" xyz="0 0 -0.046"/>
  </joint>
  <!--************************-->
  <!--        ft sensor       -->
  <!--************************-->
  <link name="wrist_left_ft_link">
    <inertial>
      <mass value="0.1"/>
      <inertia ixx="1.6E-05" ixy="-2.0E-06" ixz="0.0" iyy="1.6E-05" iyz="0.0" izz="2.7E-05"/>
    </inertial>
    <visual>
      <origin rpy="0 0 0" xyz="0 0 0"/>
      <geometry>
        <cylinder length="0.0157" radius="0.0225"/>
      </geometry>
      <material name="LightGrey"/>
    </visual>
    <collision>
      <origin rpy="0 0 0" xyz="0 0 0"/>
      <geometry>
        <cylinder length="0.0157" radius="0.0225"/>
      </geometry>
    </collision>
  </link>
  <joint name="wrist_left_ft_joint" type="fixed">
    <parent link="arm_left_tool_link"/>
    <child link="wrist_left_ft_link"/>
    <origin rpy="1.57079632679 0 1.57079632679" xyz="0.00785 0 0"/>
  </joint>
  <!--***********************-->
  <!--       FT TOOL         -->
  <!--***********************-->
  <link name="wrist_left_ft_tool_link">
    <inertial>
      <mass value="0.1"/>
      <inertia ixx="1.64E-05" ixy="0.0" ixz="0.0" iyy="1.64E-05" iyz="0.0" izz="3.125E-05"/>
    </inertial>
    <visual>
      <origin rpy="0 1.57079632679 0" xyz="0.0 0 0"/>
      <geometry>
        <cylinder length="0.00975" radius="0.025"/>
      </geometry>
      <material name="FlatBlack"/>
    </visual>
    <collision>
      <origin rpy="0 1.57079632679 0" xyz="0.0 0 0"/>
      <geometry>
        <cylinder length="0.00975" radius="0.025"/>
      </geometry>
    </collision>
  </link>
  <joint name="wrist_left_tool_joint" type="fixed">
    <parent link="wrist_left_ft_link"/>
    <child link="wrist_left_ft_tool_link"/>
    <origin rpy="-1.57079632679 -1.57079632679 0" xyz="0 0 0.012725"/>
  </joint>
  <link name="gripper_left_tool_link">
    <inertial>
      <origin rpy="0 0 0" xyz="0 0 0"/>
      <mass value="0.0001"/>
      <inertia ixx="0.00001" ixy="0.0" ixz="0.0" iyy="0.00001" iyz="0.0" izz="0.00001"/>
    </inertial>
  </link>
  <joint name="gripper_left_tool_joint" type="fixed">
    <origin rpy="1.57079632679 1.57079632679 -1.57079632679" xyz="0.01 0 0"/>
    <parent link="wrist_left_ft_tool_link"/>
    <child link="gripper_left_tool_link"/>
    <axis xyz="0 0 0"/>
  </joint>
  <link name="gripper_left_link">
    <inertial>
      <origin rpy="0.0 0.0 0.0" xyz="-0.000294 0.000291 -0.033086"/>
      <mass value="0.602660"/>
      <inertia ixx="0.000693" ixy="0.000045" ixz="-0.000000" iyy="0.001024" iyz="0.000000" izz="0.000672"/>
    </inertial>
    <visual>
      <origin rpy="0 0 0" xyz="0 0 0"/>
      <geometry>
        <mesh filename="pal_gripper_description/meshes/gripper_link.stl"/>
      </geometry>
      <material name="White"/>
    </visual>
    <collision>
      <origin rpy="0 0 0" xyz="0 0 0"/>
      <geometry>
        <mesh filename="pal_gripper_description/meshes/gripper_link_collision.stl"/>
      </geometry>
    </collision>
  </link>
  <joint name="gripper_left_joint" type="fixed">
    <origin rpy="1.57079632679 1.57079632679 -1.57079632679" xyz="0.01 0 0"/>
    <parent link="wrist_left_ft_tool_link"/>
    <child link="gripper_left_link"/>
    <axis xyz="0 0 0"/>
  </joint>
  <link name="gripper_left_right_finger_link">
    <inertial>
      <origin rpy="0 0 0" xyz="-0.004470 0.010766 -0.121013"/>
      <mass value="0.109980"/>
      <inertia ixx="0.000232" ixy="-0.000005" ixz="-0.000032" iyy="0.000224" iyz="0.000036" izz="0.000029"/>
    </inertial>
    <visual>
      <origin rpy="0 0 3.1415" xyz="0 0 0"/>
      <geometry>
        <mesh filename="pal_gripper_description/meshes/gripper_finger_link.stl" scale="-1 -1 1"/>
      </geometry>
      <material name="Black"/>
    </visual>
    <collision>
      <origin rpy="0 0 3.1415" xyz="0.005 0 -0.165"/>
      <geometry>
        <box size="0.01 0.05 0.11"/>
      </geometry>
    </collision>
  </link>
  <joint name="gripper_left_right_finger_joint" type="prismatic">
    <origin rpy="0 0 0" xyz="0. 0 0"/>
    <parent link="gripper_left_link"/>
    <child link="gripper_left_right_finger_link"/>
    <axis xyz="1 0 0"/>
    <limit effort="16" lower="0.0" upper="0.045" velocity="0.05"/>
    <calibration rising="0.0"/>
    <dynamics damping="80"/>
    <safety_controller k_position="20" k_velocity="20" soft_lower_limit="0.001" soft_upper_limit="0.044"/>
  </joint>
  <link name="gripper_left_left_finger_link">
    <inertial>
      <origin rpy="0 0 0" xyz="-0.004470 0.010766 -0.121013"/>
      <mass value="0.109980"/>
      <inertia ixx="0.000232" ixy="-0.000005" ixz="-0.000032" iyy="0.000224" iyz="0.000036" izz="0.000029"/>
    </inertial>
    <visual>
      <origin rpy="0 0 3.1415" xyz="0 0 0"/>
      <geometry>
        <mesh filename="pal_gripper_description/meshes/gripper_finger_link.stl"/>
      </geometry>
      <material name="Black"/>
    </visual>
    <collision>
      <origin rpy="0 0 3.1415" xyz="-0.005 0 -0.165"/>
      <geometry>
        <box size="0.01 0.05 0.11"/>
      </geometry>
    </collision>
  </link>
  <joint name="gripper_left_left_finger_joint" type="prismatic">
    <origin rpy="0 0 0" xyz="0. 0 0"/>
    <parent link="gripper_left_link"/>
    <child link="gripper_left_left_finger_link"/>
    <axis xyz="-1 0 0"/>
    <limit effort="16" lower="0" upper="0.045" velocity="0.05"/>
    <calibration rising="0.0"/>
    <dynamics damping="80"/>
    <safety_controller k_position="20" k_velocity="20" soft_lower_limit="0.001" soft_upper_limit="0.044"/>
  </joint>
  <!-- Grasping frame -->
  <joint name="gripper_left_grasping_frame_joint" type="fixed">
    <parent link="gripper_left_link"/>
    <child link="gripper_left_grasping_frame"/>
    <origin rpy="-1.5708 1.5708 0" xyz="0 0 -0.12"/>
  </joint>
  <link name="gripper_left_grasping_frame">
    <inertial>
      <origin rpy="0 0 0" xyz="0 0 0"/>
      <mass value="0.0001"/>
      <inertia ixx="0.00001" ixy="0.0" ixz="0.0" iyy="0.00001" iyz="0.0" izz="0.00001"/>
    </inertial>
  </link>
  <!-- Schunk WSG 
  <xacro:if value="${type == 'schunk-wsg'}">
    <xacro:include filename="$(find pal_wsg_gripper_description)/urdf/gripper.urdf.xacro" />
    <xacro:include filename="$(find pal_wsg_gripper_description)/urdf/fingertip_sensor.urdf.xacro" />

    <xacro:pal_wsg_gripper parent="${parent}" name="${name}">
      <origin xyz="0.01 0 0" rpy="${90*deg_to_rad} ${90*deg_to_rad} ${-90*deg_to_rad}"/>
    </xacro:pal_wsg_gripper>
    <xacro:fingertip_sensor name="${name}_left" parent="${name}_left_finger">
      <origin xyz="0.035 0 -0.1465" rpy="0 ${-90*deg_to_rad} 0"/>
    </xacro:fingertip_sensor>
    <xacro:fingertip_sensor name="${name}_right" parent="${name}_right_finger">
      <origin xyz="-0.035 0 -0.1465" rpy="0 ${90*deg_to_rad} 0"/>
    </xacro:fingertip_sensor>
  </xacro:if>
-->
  <!-- Hand 
  <xacro:if value="${type == 'pal-hey5'}">
    <xacro:hey5_hand parent="${parent}" name="${name}" reflect="${reflect}">
      <origin xyz="0 0 0" rpy="0 0 0"/>
    </xacro:hey5_hand>

    <joint name="${name}_safety_box_joint" type="fixed">
      <parent link="${parent}"/>
      <child link="${name}_safety_box"/>
      <origin xyz="0.1 0.02 ${reflect * 0.02}" rpy="0 0 0"/>
    </joint>

    <link name="${name}_safety_box">
      <inertial>
        <origin xyz="0 0 0" rpy="0 0 0"/>
        <mass value="0.0001" />
        <inertia ixx="0.0001"  ixy="0"  ixz="0" iyy="0.0001" iyz="0" izz="0.0001" />
      </inertial>
      <collision>
        <origin xyz="0 0 0" rpy="0 0 0" />
        <geometry>
          <box size="0.2 0.115 0.18" />
        </geometry>
      </collision>
    </link>
  </xacro:if>
-->
  <!-- Robotiq 2F-85 Gripper 
  <xacro:if value="${type == 'robotiq-2f-85'}">
    <xacro:include filename="$(find pal_robotiq_85_description)/urdf/robotiq_85_gripper.urdf.xacro" />
    <xacro:robotiq_85_gripper prefix="${name}_" parent="${parent}" >
      <origin xyz="0.01 0 0" rpy="${90*deg_to_rad} ${0*deg_to_rad} ${90*deg_to_rad}"/>
    </xacro:robotiq_85_gripper>
  </xacro:if>
-->
  <!-- Robotiq 2F-140 Gripper 
  <xacro:if value="${type == 'robotiq-2f-140'}">
    <xacro:include filename="$(find pal_robotiq_140_description)/urdf/robotiq_140_gripper.urdf.xacro" />
    <xacro:robotiq_140_gripper prefix="${name}_" parent="${parent}" >
      <origin xyz="0.01 0 0" rpy="${90*deg_to_rad} ${0*deg_to_rad} ${90*deg_to_rad}"/>
    </xacro:robotiq_140_gripper>
  </xacro:if>
-->
  <!-- Custom 
  <xacro:if value="${type == 'custom' and not is_dual}">
    <xacro:include filename="$(find custom_ee_description)/urdf/end-effector.urdf.xacro" />
    <xacro:end_effector parent="${parent}">
      <origin xyz="0.01 0 0" rpy="${90*deg_to_rad} ${90*deg_to_rad} ${-90*deg_to_rad}"/>
    </xacro:end_effector>
  </xacro:if>
-->
  <!-- Custom dual
  <xacro:if value="${type == 'custom' and is_dual}">
    <xacro:if value="${reflect == 1}"> 
 If right 
    <xacro:include filename="$(find custom_dual_ee_description)/urdf/end-effector-right.urdf.xacro" />
    <xacro:end_effector_right parent="${parent}">
      <origin xyz="0.01 0 0" rpy="${90*deg_to_rad} ${90*deg_to_rad} ${-90*deg_to_rad}"/>
    </xacro:end_effector_right>
    </xacro:if>
    <xacro:if value="${reflect == -1}">  If left 
    <xacro:include filename="$(find custom_dual_ee_description)/urdf/end-effector-left.urdf.xacro" />
    <xacro:end_effector_left parent="${parent}">
      <origin xyz="0.01 0 0" rpy="${90*deg_to_rad} ${90*deg_to_rad} ${-90*deg_to_rad}"/>
    </xacro:end_effector_left>
    </xacro:if>
  </xacro:if>
-->
  <!--************************-->
  <!--        SHOULDER        -->
  <!--************************-->
  <link name="arm_right_1_link">
    <inertial>
      <!--<origin xyz="0.061191 ${reflect * -0.022397} -0.012835" rpy="0.00000 0.00000 0.00000"/>-->
      <origin rpy="0.00000 0.00000 0.00000" xyz="0.061191 -0.022397 -0.012835"/>
      <mass value="1.563428"/>
      <inertia ixx="0.002471" ixy="-0.001809" ixz="-0.001202" iyy="0.006132" iyz="0.000494" izz="0.006704"/>
    </inertial>
    <!-- M90 module -->
    <visual>
      <origin rpy="0 0 0" xyz="0 0 0"/>
      <geometry>
        <mesh filename="tiago_description/meshes/arm/arm_1.stl" scale="1 -1 1"/>
      </geometry>
      <material name="White"/>
    </visual>
    <collision>
      <origin rpy="0 0 0" xyz="0 0 0"/>
      <geometry>
        <mesh filename="tiago_description/meshes/arm/arm_1_collision.dae" scale="1 -1 1"/>
      </geometry>
    </collision>
  </link>
  <joint name="arm_right_1_joint" type="revolute">
    <parent link="torso_lift_link"/>
    <child link="arm_right_1_link"/>
    <origin rpy="0 0 -1.57079632679" xyz="0.02556 -0.19 -0.171"/>
    <axis xyz="0 0 1"/>
    <limit effort="43.0" lower="-1.1780972451" upper="1.57079632679" velocity="1.95"/>
    <dynamics damping="1.0" friction="1.0"/>
    <safety_controller k_position="20" k_velocity="20" soft_lower_limit="-1.1080972451" soft_upper_limit="1.50079632679"/>
  </joint>
  <link name="arm_right_2_link">
    <inertial>
      <origin rpy="0.00000 0.00000 0.00000" xyz="0.030432 0.000229 -0.005942"/>
      <mass value="1.800397"/>
      <inertia ixx="0.001809" ixy="1.5e-05" ixz="0.000254" iyy="0.004333" iyz="1.4e-05" izz="0.004341"/>
    </inertial>
    <visual>
      <!-- <origin xyz="0 0 0" rpy="${180 * deg_to_rad} ${0 * deg_to_rad} ${-90 * deg_to_rad}" /> -->
      <origin rpy="0.0 0.0 0.0" xyz="0 0 0"/>
      <geometry>
        <mesh filename="tiago_description/meshes/arm/arm_2.stl" scale="1 1 1"/>
      </geometry>
      <material name="DarkGrey"/>
    </visual>
    <collision>
      <!-- <origin xyz="0 0 0" rpy="${180 * deg_to_rad} ${0 * deg_to_rad} ${-90 * deg_to_rad}" /> -->
      <origin rpy="0.0 0.0 0.0" xyz="0 0 0"/>
      <geometry>
        <mesh filename="tiago_description/meshes/arm/arm_2_collision.dae" scale="1 1 1"/>
      </geometry>
    </collision>
  </link>
  <joint name="arm_right_2_joint" type="revolute">
    <parent link="arm_right_1_link"/>
    <child link="arm_right_2_link"/>
    <origin rpy="-1.57079632679 0.0 0.0" xyz="0.125 -0.0195 -0.031"/>
    <axis xyz="0 0 1"/>
    <limit effort="43.0" lower="-1.1780972451" upper="1.57079632679" velocity="1.95"/>
    <dynamics damping="1.0" friction="1.0"/>
    <safety_controller k_position="20" k_velocity="20" soft_lower_limit="-1.1080972451" soft_upper_limit="1.50079632679"/>
  </joint>
  <link name="arm_right_3_link">
    <inertial>
      <origin rpy="0.00000 0.00000 0.00000" xyz="0.007418 -0.004361 -0.134194"/>
      <mass value="1.8"/>
      <inertia ixx="0.019541" ixy="-0.000105" ixz="-0.001717" iyy="0.019936" iyz="0.000852" izz="0.002864"/>
    </inertial>
    <visual>
      <origin rpy="0 0 0" xyz="0 0 0"/>
      <geometry>
        <mesh filename="tiago_description/meshes/arm/arm_3.stl" scale="1 1 1"/>
      </geometry>
      <material name="DarkGrey"/>
    </visual>
    <collision>
      <origin rpy="0 0 0" xyz="0 0 0"/>
      <geometry>
        <mesh filename="tiago_description/meshes/arm/arm_3_collision.dae" scale="1 1 1"/>
      </geometry>
    </collision>
  </link>
  <joint name="arm_right_3_joint" type="revolute">
    <parent link="arm_right_2_link"/>
    <child link="arm_right_3_link"/>
    <origin rpy="-1.57079632679 0.0 1.57079632679" xyz="0.0895 0.0 -0.0015"/>
    <axis xyz="0 0 1"/>
    <limit effort="26" lower="-0.785398163397" upper="3.92699081699" velocity="2.35"/>
    <dynamics damping="1.0" friction="1.0"/>
    <safety_controller k_position="20" k_velocity="20" soft_lower_limit="-0.715398163397" soft_upper_limit="3.85699081699"/>
  </joint>
  <!--************************-->
  <!--        ELBOW           -->
  <!--************************-->
  <link name="arm_right_4_link">
    <inertial>
      <origin rpy="0.00000 0.00000 0.00000" xyz="-0.095658 0.014666 0.018133"/>
      <mass value="1.432697"/>
      <inertia ixx="0.002040" ixy="0.000725" ixz="-0.00115" iyy="0.008424" iyz="-0.000204" izz="0.008686"/>
    </inertial>
    <visual>
      <origin rpy="0 0 0" xyz="0 0 0"/>
      <geometry>
        <mesh filename="tiago_description/meshes/arm/arm_4.stl" scale="1 1 1"/>
      </geometry>
      <material name="DarkGrey"/>
    </visual>
    <collision>
      <origin rpy="0 0 0" xyz="0 0 0"/>
      <geometry>
        <mesh filename="tiago_description/meshes/arm/arm_4_collision.dae" scale="1 1 1"/>
      </geometry>
    </collision>
  </link>
  <joint name="arm_right_4_joint" type="revolute">
    <parent link="arm_right_3_link"/>
    <child link="arm_right_4_link"/>
    <origin rpy="-1.57079632679 -1.57079632679 0.0" xyz="-0.02 -0.027 -0.222"/>
    <axis xyz="0 0 1"/>
    <limit effort="26" lower="-0.392699081699" upper="2.35619449019" velocity="2.35"/>
    <dynamics damping="1.0" friction="1.0"/>
    <safety_controller k_position="20" k_velocity="20" soft_lower_limit="-0.322699081699" soft_upper_limit="2.28619449019"/>
  </joint>
  <!--************************-->
  <!--        WRIST           -->
  <!--************************-->
  <!--************************-->
  <!--        WRIST           -->
  <!--************************-->
  <link name="arm_right_5_link">
    <inertial>
      <origin rpy="0.00000 0.00000 0.00000" xyz="0.001078 -0.000151 -0.077173"/>
      <mass value="1.655819"/>
      <inertia ixx="0.00613800000" ixy="-0.00000400000" ixz="0.00015600000" iyy="0.00564000000" iyz="0.00002200000" izz="0.00179700000"/>
    </inertial>
    <visual>
      <origin rpy="0 0 0" xyz="0 0 0"/>
      <geometry>
        <mesh filename="tiago_description/meshes/arm/arm_5-wrist-2010.stl" scale="1 1 1"/>
      </geometry>
      <material name="LightGrey"/>
    </visual>
    <collision>
      <origin rpy="0 0 0" xyz="0 0 0"/>
      <geometry>
        <mesh filename="tiago_description/meshes/arm/arm_5_collision-wrist-2010.dae" scale="1 1 1"/>
      </geometry>
    </collision>
  </link>
  <joint name="arm_right_5_joint" type="revolute">
    <parent link="arm_right_4_link"/>
    <child link="arm_right_5_link"/>
    <origin rpy="1.57079632679 -1.57079632679 -1.57079632679" xyz="-0.162 0.02 0.027"/>
    <axis xyz="0 0 1"/>
    <limit effort="3" lower="-2.09439510239" upper="2.09439510239" velocity="1.95"/>
    <dynamics damping="1.0" friction="1.0"/>
    <safety_controller k_position="20" k_velocity="20" soft_lower_limit="-2.07439510239" soft_upper_limit="2.07439510239"/>
  </joint>
  <link name="arm_right_6_link">
    <inertial>
      <origin rpy="0.00000 0.00000 0.00000" xyz="-0.000153 -0.003122 0.000183"/>
      <mass value="0.370063"/>
      <inertia ixx="0.00021500000" ixy="0.00000000000" ixz="0.00000000000" iyy="0.00017000000" iyz="0.00000200000" izz="0.00017400000"/>
    </inertial>
    <visual>
      <origin rpy="0 0 0" xyz="0 0 0"/>
      <geometry>
        <mesh filename="tiago_description/meshes/arm/arm_6-wrist-2010.stl" scale="1 1 1"/>
      </geometry>
      <material name="LightGrey"/>
    </visual>
    <collision>
      <origin rpy="0 0 0" xyz="0 0 0"/>
      <geometry>
        <mesh filename="tiago_description/meshes/arm/arm_6_collision-wrist-2010.dae" scale="1 1 1"/>
      </geometry>
    </collision>
  </link>
  <joint name="arm_right_6_joint" type="revolute">
    <parent link="arm_right_5_link"/>
    <child link="arm_right_6_link"/>
    <origin rpy="0.0 -1.57079632679 -1.57079632679" xyz="0 0 0.15"/>
    <axis xyz="0 0 1"/>
    <limit effort="6.6" lower="-1.41371669412" upper="1.41371669412" velocity="1.76"/>
    <dynamics damping="1.0" friction="1.0"/>
    <safety_controller k_position="20" k_velocity="20" soft_lower_limit="-1.39371669412" soft_upper_limit="1.39371669412"/>
  </joint>
  <link name="arm_right_7_link">
    <inertial>
      <origin rpy="0.00000 0.00000 0.00000" xyz="0.000010 -0.000003 -0.007774"/>
      <mass value="0.234252"/>
      <inertia ixx="0.00014200000" ixy="0.00000000000" ixz="0.00000000000" iyy="0.00011300000" iyz="0.00000000000" izz="0.00005200000"/>
    </inertial>
  </link>
  <joint name="arm_right_7_joint" type="revolute">
    <parent link="arm_right_6_link"/>
    <child link="arm_right_7_link"/>
    <origin rpy="1.57079632679 0.0 1.57079632679" xyz="0 0 0"/>
    <axis xyz="0 0 1"/>
    <limit effort="6.6" lower="-2.09439510239" upper="2.09439510239" velocity="1.76"/>
    <dynamics damping="1.0" friction="1.0"/>
    <safety_controller k_position="20" k_velocity="20" soft_lower_limit="-2.07439510239" soft_upper_limit="2.07439510239"/>
  </joint>
  <!--***********************-->
  <!--        TOOL           -->
  <!--***********************-->
  <link name="arm_right_tool_link">
    <inertial>
      <mass value="0.1"/>
      <inertia ixx="8.33E-07" ixy="0.0" ixz="0.0" iyy="8.33E-07" iyz="0.0" izz="1.25E-06"/>
    </inertial>
    <visual>
      <origin rpy="0 1.57079632679 0" xyz="0.001 0 0"/>
      <geometry>
        <cylinder length="0.005" radius="0.005"/>
      </geometry>
      <material name="LightGrey"/>
    </visual>
    <collision>
      <origin rpy="0 1.57079632679 0" xyz="0.001 0 0"/>
      <geometry>
        <cylinder length="0.005" radius="0.005"/>
      </geometry>
    </collision>
  </link>
  <joint name="arm_right_tool_joint" type="fixed">
    <parent link="arm_right_7_link"/>
    <child link="arm_right_tool_link"/>
    <origin rpy="1.57079632679 -1.57079632679 3.14159265359" xyz="0 0 0.046"/>
  </joint>
  <!--************************-->
  <!--        ft sensor       -->
  <!--************************-->
  <link name="wrist_right_ft_link">
    <inertial>
      <mass value="0.1"/>
      <inertia ixx="1.6E-05" ixy="-2.0E-06" ixz="0.0" iyy="1.6E-05" iyz="0.0" izz="2.7E-05"/>
    </inertial>
    <visual>
      <origin rpy="0 0 0" xyz="0 0 0"/>
      <geometry>
        <cylinder length="0.0157" radius="0.0225"/>
      </geometry>
      <material name="LightGrey"/>
    </visual>
    <collision>
      <origin rpy="0 0 0" xyz="0 0 0"/>
      <geometry>
        <cylinder length="0.0157" radius="0.0225"/>
      </geometry>
    </collision>
  </link>
  <joint name="wrist_right_ft_joint" type="fixed">
    <parent link="arm_right_tool_link"/>
    <child link="wrist_right_ft_link"/>
    <origin rpy="1.57079632679 0 1.57079632679" xyz="0.00785 0 0"/>
  </joint>
  <!--***********************-->
  <!--       FT TOOL         -->
  <!--***********************-->
  <link name="wrist_right_ft_tool_link">
    <inertial>
      <mass value="0.1"/>
      <inertia ixx="1.64E-05" ixy="0.0" ixz="0.0" iyy="1.64E-05" iyz="0.0" izz="3.125E-05"/>
    </inertial>
    <visual>
      <origin rpy="0 1.57079632679 0" xyz="0.0 0 0"/>
      <geometry>
        <cylinder length="0.00975" radius="0.025"/>
      </geometry>
      <material name="FlatBlack"/>
    </visual>
    <collision>
      <origin rpy="0 1.57079632679 0" xyz="0.0 0 0"/>
      <geometry>
        <cylinder length="0.00975" radius="0.025"/>
      </geometry>
    </collision>
  </link>
  <joint name="wrist_right_tool_joint" type="fixed">
    <parent link="wrist_right_ft_link"/>
    <child link="wrist_right_ft_tool_link"/>
    <origin rpy="-1.57079632679 -1.57079632679 0" xyz="0 0 0.012725"/>
  </joint>
  <link name="gripper_right_tool_link">
    <inertial>
      <origin rpy="0 0 0" xyz="0 0 0"/>
      <mass value="0.0001"/>
      <inertia ixx="0.00001" ixy="0.0" ixz="0.0" iyy="0.00001" iyz="0.0" izz="0.00001"/>
    </inertial>
  </link>
  <joint name="gripper_right_tool_joint" type="fixed">
    <origin rpy="1.57079632679 1.57079632679 -1.57079632679" xyz="0.01 0 0"/>
    <parent link="wrist_right_ft_tool_link"/>
    <child link="gripper_right_tool_link"/>
    <axis xyz="0 0 0"/>
  </joint>
  <link name="gripper_right_link">
    <inertial>
      <origin rpy="0.0 0.0 0.0" xyz="-0.000294 0.000291 -0.033086"/>
      <mass value="0.602660"/>
      <inertia ixx="0.000693" ixy="0.000045" ixz="-0.000000" iyy="0.001024" iyz="0.000000" izz="0.000672"/>
    </inertial>
    <visual>
      <origin rpy="0 0 0" xyz="0 0 0"/>
      <geometry>
        <mesh filename="pal_gripper_description/meshes/gripper_link.stl"/>
      </geometry>
      <material name="White"/>
    </visual>
    <collision>
      <origin rpy="0 0 0" xyz="0 0 0"/>
      <geometry>
        <mesh filename="pal_gripper_description/meshes/gripper_link_collision.stl"/>
      </geometry>
    </collision>
  </link>
  <joint name="gripper_right_joint" type="fixed">
    <origin rpy="1.57079632679 1.57079632679 -1.57079632679" xyz="0.01 0 0"/>
    <parent link="wrist_right_ft_tool_link"/>
    <child link="gripper_right_link"/>
    <axis xyz="0 0 0"/>
  </joint>
  <link name="gripper_right_right_finger_link">
    <inertial>
      <origin rpy="0 0 0" xyz="-0.004470 0.010766 -0.121013"/>
      <mass value="0.109980"/>
      <inertia ixx="0.000232" ixy="-0.000005" ixz="-0.000032" iyy="0.000224" iyz="0.000036" izz="0.000029"/>
    </inertial>
    <visual>
      <origin rpy="0 0 3.1415" xyz="0 0 0"/>
      <geometry>
        <mesh filename="pal_gripper_description/meshes/gripper_finger_link.stl" scale="-1 -1 1"/>
      </geometry>
      <material name="Black"/>
    </visual>
    <collision>
      <origin rpy="0 0 3.1415" xyz="0.005 0 -0.165"/>
      <geometry>
        <box size="0.01 0.05 0.11"/>
      </geometry>
    </collision>
  </link>
  <joint name="gripper_right_right_finger_joint" type="prismatic">
    <origin rpy="0 0 0" xyz="0. 0 0"/>
    <parent link="gripper_right_link"/>
    <child link="gripper_right_right_finger_link"/>
    <axis xyz="1 0 0"/>
    <limit effort="16" lower="0.0" upper="0.045" velocity="0.05"/>
    <calibration rising="0.0"/>
    <dynamics damping="80"/>
    <safety_controller k_position="20" k_velocity="20" soft_lower_limit="0.001" soft_upper_limit="0.044"/>
  </joint>
  <link name="gripper_right_left_finger_link">
    <inertial>
      <origin rpy="0 0 0" xyz="-0.004470 0.010766 -0.121013"/>
      <mass value="0.109980"/>
      <inertia ixx="0.000232" ixy="-0.000005" ixz="-0.000032" iyy="0.000224" iyz="0.000036" izz="0.000029"/>
    </inertial>
    <visual>
      <origin rpy="0 0 3.1415" xyz="0 0 0"/>
      <geometry>
        <mesh filename="pal_gripper_description/meshes/gripper_finger_link.stl"/>
      </geometry>
      <material name="Black"/>
    </visual>
    <collision>
      <origin rpy="0 0 3.1415" xyz="-0.005 0 -0.165"/>
      <geometry>
        <box size="0.01 0.05 0.11"/>
      </geometry>
    </collision>
  </link>
  <joint name="gripper_right_left_finger_joint" type="prismatic">
    <origin rpy="0 0 0" xyz="0. 0 0"/>
    <parent link="gripper_right_link"/>
    <child link="gripper_right_left_finger_link"/>
    <axis xyz="-1 0 0"/>
    <limit effort="16" lower="0" upper="0.045" velocity="0.05"/>
    <calibration rising="0.0"/>
    <dynamics damping="80"/>
    <safety_controller k_position="20" k_velocity="20" soft_lower_limit="0.001" soft_upper_limit="0.044"/>
  </joint>
  <!-- Grasping frame -->
  <joint name="gripper_right_grasping_frame_joint" type="fixed">
    <parent link="gripper_right_link"/>
    <child link="gripper_right_grasping_frame"/>
    <origin rpy="-1.5708 1.5708 0" xyz="0 0 -0.12"/>
  </joint>
  <link name="gripper_right_grasping_frame">
    <inertial>
      <origin rpy="0 0 0" xyz="0 0 0"/>
      <mass value="0.0001"/>
      <inertia ixx="0.00001" ixy="0.0" ixz="0.0" iyy="0.00001" iyz="0.0" izz="0.00001"/>
    </inertial>
  </link>
</robot>
