<?xml version="1.0" ?>
<!-- =================================================================================== -->
<!-- |    This document was autogenerated by xacro from dingo_kinova.xacro             | -->
<!-- |    EDITING THIS FILE BY HAND IS NOT RECOMMENDED                                 | -->
<!-- =================================================================================== -->
<robot name="dingo_kinova">
  <!-- ========== -->
  <!--    LINKS   -->
  <!-- ========== -->
  <!-- ARM base link -->
  <link name="arm_base_link">
    <inertial>
      <origin rpy="0 0 0" xyz="0.00244324 0.00015573 0.08616742"/>
      <mass value="1.14608471"/>
      <inertia ixx="0.00335854" ixy="3.9E-07" ixz="0.00010989" iyy="0.003311" iyz="1.91E-06" izz="0.00077158"/>
    </inertial>
    <visual>
      <origin rpy="0 0 0" xyz="0 0 0"/>
      <geometry>
        <mesh filename="../meshes/kinova/base_link.STL" />
      </geometry>
      <material name="">
        <color rgba="0.803 0.824 0.820 1"/>
      </material>
    </visual>
    <collision>
      <origin rpy="0 0 0" xyz="0 0 0"/>
      <geometry>
         <mesh filename="../meshes/kinova/base_link.STL" />
      </geometry>
    </collision>
  </link>
  <!-- Shoulder link -->
  <link name="arm_shoulder_link">
    <inertial>
      <origin rpy="0 0 0" xyz="2.477E-05 0.02213531 0.09937686"/>
      <mass value="0.95974404"/>
      <inertia ixx="0.00165947" ixy="2E-08" ixz="3.6E-07" iyy="0.00140355" iyz="0.00034927" izz="0.00089493"/>
    </inertial>
    <visual>
      <origin rpy="0 0 0" xyz="0 0 0"/>
      <geometry>
        <mesh filename="../meshes/kinova/shoulder_link.STL"/>
      </geometry>
      <material name="">
        <color rgba="0.803 0.824 0.820 1"/>
      </material>
    </visual>
    <collision>
      <origin rpy="0 0 0" xyz="0 0 0"/>
      <geometry>
        <mesh filename="../meshes/kinova/shoulder_link.STL"/>
      </geometry>
    </collision>
  </link>
  <!-- Arm link -->
  <link name="arm_arm_link">
    <inertial>
      <origin rpy="0 0 0" xyz="0.02998299 0.21154808 0.0453031"/>
      <mass value="1.17756164"/>
      <inertia ixx="0.01149277" ixy="1E-06" ixz="1.6E-07" iyy="0.00102851" iyz="0.00140765" izz="0.01133492"/>
    </inertial>
    <visual>
      <origin rpy="0 0 0" xyz="0 0 0"/>
      <geometry>
        <mesh filename="../meshes/kinova/arm_link.STL"/>
      </geometry>
      <material name="">
        <color rgba="0.803 0.824 0.820 1"/>
      </material>
    </visual>
    <collision>
      <origin rpy="0 0 0" xyz="0 0 0"/>
      <geometry>
        <mesh filename="../meshes/kinova/arm_link.STL"/>
      </geometry>
    </collision>
  </link>
  <!-- Forearm link -->
  <link name="arm_forearm_link">
    <inertial>
      <origin rpy="0 0 0" xyz="0.0301559 0.09502206 0.0073555"/>
      <mass value="0.59767669"/>
      <inertia ixx="0.00163256" ixy="7.11E-06" ixz="1.54E-06" iyy="0.00029798" iyz="9.587E-05" izz="0.00169091"/>
    </inertial>
    <visual>
      <origin rpy="0 0 0" xyz="0 0 0"/>
      <geometry>
        <mesh filename="../meshes/kinova/forearm_link.STL"/>
      </geometry>
      <material name="">
        <color rgba="0.803 0.824 0.820 1"/>
      </material>
    </visual>
    <collision>
      <origin rpy="0 0 0" xyz="0 0 0"/>
      <geometry>
        <mesh filename="../meshes/kinova/forearm_link.STL"/>
      </geometry>
    </collision>
  </link>
  <!-- Lower_wrist_link  -->
  <link name="arm_lower_wrist_link">
    <inertial>
      <origin rpy="0 0 0" xyz="0.00575149 0.01000443 0.08719207"/>
      <mass value="0.52693412"/>
      <inertia ixx="0.00069098" ixy="2.4E-07" ixz="0.00016483" iyy="0.00078519" iyz="7.4E-07" izz="0.00034115"/>
    </inertial>
    <visual>
      <origin rpy="0 0 0" xyz="0 0 0"/>
      <geometry>
        <mesh filename="../meshes/kinova/lower_wrist_link.STL"/>
      </geometry>
      <material name="">
        <color rgba="0.803 0.824 0.820 1"/>
      </material>
    </visual>
    <collision>
      <origin rpy="0 0 0" xyz="0 0 0"/>
      <geometry>
        <mesh filename="../meshes/kinova/lower_wrist_link.STL"/>
      </geometry>
    </collision>
  </link>
  <!-- Upper_wrist_link -->
  <link name="arm_upper_wrist_link">
    <inertial>
      <origin rpy="0 0 0" xyz="0.08056517 0.00980409 0.01872799"/>
      <mass value="0.58097325"/>
      <inertia ixx="0.00021268" ixy="5.21E-06" ixz="2.91E-06" iyy="0.00106371" iyz="1.1E-07" izz="0.00108465"/>
    </inertial>
    <visual>
      <origin rpy="0 0 0" xyz="0 0 0"/>
      <geometry>
        <mesh filename="../meshes/kinova/upper_wrist_link.STL"/>
      </geometry>
      <material name="">
        <color rgba="0.803 0.824 0.820 1"/>
      </material>
    </visual>
    <collision>
      <origin rpy="0 0 0" xyz="0 0 0"/>
      <geometry>
        <mesh filename="../meshes/kinova/upper_wrist_link.STL"/>
      </geometry>
    </collision>
  </link>
  <!-- Dummy links for transforming axes -->
  <link name="arm_end_effector_link">
    <inertial>
      <mass value="0.0001"/>
      <origin rpy="0 0 0" xyz="0 0 0"/>
      <inertia ixx="0.0001" ixy="0.0" ixz="0.0" iyy="0.0001" iyz="0.0" izz="0.0001"/>
    </inertial>
  </link>
  <link name="arm_dummy_link"/>
  <link name="arm_tool_frame"/>
  <!-- ================= -->
  <!-- Revolute JOINTS   -->
  <!-- ================= -->
  <!-- Joint 1 -->
  <joint name="arm_joint_1" type="revolute">
    <origin rpy="0 0 0" xyz="0 0 0.12825"/>
    <parent link="arm_base_link"/>
    <child link="arm_shoulder_link"/>
    <axis xyz="0 0 1"/>
    <limit effort="10" lower="-2.68" upper="2.68" velocity="1.6"/>
  </joint>
  <!-- Joint 2 -->
  <joint name="arm_joint_2" type="revolute">
    <origin rpy="1.5708 0 0" xyz="0 -0.03 0.115"/>
    <parent link="arm_shoulder_link"/>
    <child link="arm_arm_link"/>
    <axis xyz="0 0 1"/>
    <limit effort="14" lower="-2.61" upper="2.61" velocity="1.6"/>
  </joint>
  <!-- Joint 3 -->
  <joint name="arm_joint_3" type="revolute">
    <origin rpy="-3.1416 0 0" xyz="0 0.28 0"/>
    <parent link="arm_arm_link"/>
    <child link="arm_forearm_link"/>
    <axis xyz="0 0 1"/>
    <limit effort="10" lower="-2.61" upper="2.61" velocity="1.6"/>
  </joint>
  <!-- Joint 4 -->
  <joint name="arm_joint_4" type="revolute">
    <origin rpy="1.5708 0 0" xyz="0 -0.14 0.02"/>
    <parent link="arm_forearm_link"/>
    <child link="arm_lower_wrist_link"/>
    <axis xyz="0 0 1"/>
    <limit effort="39" lower="-2.57" upper="2.57" velocity="1.3963"/>
  </joint>
  <!-- Joint 5 -->
  <joint name="arm_joint_5" type="revolute">
    <origin rpy="0 1.5708 0" xyz="0.0285 0 0.105"/>
    <parent link="arm_lower_wrist_link"/>
    <child link="arm_upper_wrist_link"/>
    <axis xyz="0 0 1"/>
    <limit effort="7" lower="-2.53" upper="2.53" velocity="1.6"/>
  </joint>
  <!-- Joint 6 -->
  <joint name="arm_joint_6" type="revolute">
    <origin rpy="0 -1.5708 0" xyz="-0.105 0 0.0285"/>
    <parent link="arm_upper_wrist_link"/>
    <child link="arm_end_effector_link"/>
    <axis xyz="0 0 1"/>
    <limit effort="9" lower="-2.09" upper="2.09" velocity="1.2218"/>
  </joint>
  <!-- ================= -->
  <!-- Fixed JOINTS      -->
  <!-- ================= -->
  <joint name="arm_end_effector" type="fixed">
    <origin rpy="0 0 0" xyz="0 0 0"/>
    <parent link="arm_end_effector_link"/>
    <child link="arm_dummy_link"/>
    <axis xyz="0 0 1"/>
    <limit effort="0" lower="0" upper="0" velocity="0"/>
  </joint>
  <!-- Tool frame used by the arm -->
  <joint name="arm_tool_frame_joint" type="fixed">
    <origin rpy="0 0 0" xyz="0 0 0.130"/>
    <parent link="arm_dummy_link"/>
    <child link="arm_tool_frame"/>
    <axis xyz="0 0 0"/>
  </joint>
 
  <!-- ================= -->
  <!--        JOINTS     -->
  <!-- ================= -->
  

  <!-- Define materials -->
  <material name="dark_grey">
    <color rgba="0.2 0.2 0.2 1.0"/>
  </material>
  <material name="light_grey">
    <color rgba="0.4 0.4 0.4 1.0"/>
  </material>
  <material name="yellow">
    <color rgba="0.8 0.8 0.0 1.0"/>
  </material>
  <material name="black">
    <color rgba="0.15 0.15 0.15 1.0"/>
  </material>
  <material name="aluminum">
    <color rgba="0.5 0.5 0.5 1"/>
  </material>
  <material name="plastic">
    <color rgba="0.1 0.1 0.1 1"/>
  </material>
  <!-- ============================= -->
  <!-- Omni base link transformation -->
  <!-- ============================= -->
  <link name="base_link">
    <inertial>
      <mass value="1.0"/>
      <origin rpy="0 0 0" xyz="0 0 0"/>
      <inertia ixx="1.0" ixy="0.0" ixz="0.0" iyy="1.0" iyz="0.0" izz="1.0"/>
    </inertial>
  </link>
  <link name="base_link_x">
    <inertial>
      <mass value="1.0"/>
      <origin rpy="0 0 0" xyz="0 0 0"/>
      <inertia ixx="1.0" ixy="0.0" ixz="0.0" iyy="1.0" iyz="0.0" izz="1.0"/>
    </inertial>
  </link>
  <link name="base_link_y">
    <inertial>
      <mass value="1.0"/>
      <origin rpy="0 0 0" xyz="0 0 0"/>
      <inertia ixx="1.0" ixy="0.0" ixz="0.0" iyy="1.0" iyz="0.0" izz="1.0"/>
    </inertial>
  </link>
  <!-- =============================== -->
  <!-- Omni base joints transformation -->
  <!-- =============================== -->
  <joint name="omni_joint_x" type="prismatic">
    <safety_controller k_position="100.0" k_velocity="40.0" soft_lower_limit="-500" soft_upper_limit="500"/>
    <parent link="base_link"/>
    <child link="base_link_x"/>
    <origin rpy="0 0 0" xyz="0 0 0.03"/>
    <axis xyz="1 0 0"/>
    <dynamics damping="100.0"/>
    <limit effort="1000" lower="-10" stiffness="1000" upper="10" velocity="2"/>
  </joint>
  <joint name="omni_joint_y" type="prismatic">
    <safety_controller k_position="100.0" k_velocity="40.0" soft_lower_limit="-500" soft_upper_limit="500"/>
    <parent link="base_link_x"/>
    <child link="base_link_y"/>
    <origin rpy="0 0 0" xyz="0 0 0"/>
    <axis xyz="0 1 0"/>
    <dynamics damping="100.0"/>
    <limit effort="1000" lower="-10" stiffness="1000" upper="10" velocity="2"/>
  </joint>
  <joint name="omni_joint_theta" type="revolute">
    <safety_controller k_position="100.0" k_velocity="40.0" soft_lower_limit="-500" soft_upper_limit="500"/>
    <parent link="base_link_y"/>
    <child link="chassis_link"/>
    <origin rpy="0 0 0" xyz="0 0 0"/>
    <axis xyz="0 0 1"/>
    <dynamics damping="100.0"/>
    <limit effort="1000" lower="-6.283184" stiffness="1000" upper="6.283184" velocity="2"/>
  </joint>
  <!-- =============== -->
  <!--    Robot links -->
  <!-- =============== -->
  <!-- Chassis link -->
  <link name="chassis_link">
    <visual>
      <origin rpy="0 0 0" xyz="0 0 0"/>
      <geometry>
        <mesh filename="../meshes/base/omni_chassis.dae"/>
      </geometry>
      <material name="dark_grey"/>
    </visual>
    <collision>
      <origin xyz="0 0 0"/>
      <geometry>
        <mesh filename="../meshes/base/omni_chassis_collision.stl"/>
      </geometry>
    </collision>
    <inertial>
      <!-- Center of mass -->
      <origin rpy="0 0 0" xyz="0 0 0"/>
      <mass value="14"/>
      <!-- Moments of inertia: ( chassis without wheels ) -->
      <inertia ixx="0.35498" ixy="0" ixz="0" iyy="0.7266" iyz="0" izz="1.0553"/>
    </inertial>
  </link>
  <!-- Front left wheel link -->
  <link name="front_left_wheel_link">
    <visual>
      <origin rpy="1.5707963267948966 0 0" xyz="0 0 0"/>
      <geometry>
        <cylinder length="0.05" radius="0.05"/>
      </geometry>
      <material name="black"/>
    </visual>
    <collision>
      <origin rpy="1.5707963267948966 0 0" xyz="0 0 0"/>
      <geometry>
        <cylinder length="0.05" radius="0.05"/>
      </geometry>
    </collision>
    <inertial>
      <origin rpy="0 0 0" xyz="0 0 0"/>
      <mass value="0.4"/>
      <inertia ixx="0.0003234" ixy="0" ixz="0" iyy="0.0003234" iyz="0" izz="0.0004901"/>
    </inertial>
  </link>
  <!-- Front right wheel link -->
  <link name="front_right_wheel_link">
    <visual>
      <origin rpy="1.5707963267948966 0 0" xyz="0 0 0"/>
      <geometry>
        <cylinder length="0.05" radius="0.05"/>
      </geometry>
      <material name="black"/>
    </visual>
    <collision>
      <origin rpy="1.5707963267948966 0 0" xyz="0 0 0"/>
      <geometry>
        <cylinder length="0.05" radius="0.05"/>
      </geometry>
    </collision>
    <inertial>
      <origin rpy="0 0 0" xyz="0 0 0"/>
      <mass value="0.4"/>
      <inertia ixx="0.0003234" ixy="0" ixz="0" iyy="0.0003234" iyz="0" izz="0.0004901"/>
    </inertial>
  </link>
  <!-- Rear left wheel link -->
  <link name="rear_left_wheel_link">
    <visual>
      <origin rpy="1.5707963267948966 0 0" xyz="0 0 0"/>
      <geometry>
        <cylinder length="0.05" radius="0.05"/>
      </geometry>
      <material name="black"/>
    </visual>
    <collision>
      <origin rpy="1.5707963267948966 0 0" xyz="0 0 0"/>
      <geometry>
        <cylinder length="0.05" radius="0.05"/>
      </geometry>
    </collision>
    <inertial>
      <origin rpy="0 0 0" xyz="0 0 0"/>
      <mass value="0.4"/>
      <inertia ixx="0.0003234" ixy="0" ixz="0" iyy="0.0003234" iyz="0" izz="0.0004901"/>
    </inertial>
  </link>
  <!-- Rear right wheel link -->
  <link name="rear_right_wheel_link">
    <visual>
      <origin rpy="1.5707963267948966 0 0" xyz="0 0 0"/>
      <geometry>
        <cylinder length="0.05" radius="0.05"/>
      </geometry>
      <material name="black"/>
    </visual>
    <collision>
      <origin rpy="1.5707963267948966 0 0" xyz="0 0 0"/>
      <geometry>
        <cylinder length="0.05" radius="0.05"/>
      </geometry>
    </collision>
    <inertial>
      <origin rpy="0 0 0" xyz="0 0 0"/>
      <mass value="0.4"/>
      <inertia ixx="0.0003234" ixy="0" ixz="0" iyy="0.0003234" iyz="0" izz="0.0004901"/>
    </inertial>
  </link>
  <!-- Mounting points -->
  <link name="front_mount"/>
  <link name="front_b_mount"/>
  <link name="front_c_mount"/>
  <link name="rear_mount"/>
  <link name="rear_b_mount"/>
  <link name="rear_c_mount"/>
  <link name="mid_mount"/>
  <link name="front_bumper_mount"/>
  <!-- =============== -->
  <!--   Robot joints -->
  <!-- =============== -->
  <!-- Front right wheel joint -->
  <joint name="front_left_wheel" type="fixed">
    <parent link="chassis_link"/>
    <child link="front_left_wheel_link"/>
    <origin rpy="0 0 0" xyz="0.285 0.2104 0.035145"/>
    <axis xyz="0 1 0"/>
  </joint>
  <!-- Front left wheel joint -->
  <joint name="front_right_wheel" type="fixed">
    <parent link="chassis_link"/>
    <child link="front_right_wheel_link"/>
    <origin rpy="0 0 0" xyz="0.285 -0.2104 0.035145"/>
    <axis xyz="0 1 0"/>
  </joint>
  <!-- Rear left wheel joint -->
  <joint name="rear_left_wheel" type="fixed">
    <parent link="chassis_link"/>
    <child link="rear_left_wheel_link"/>
    <origin rpy="0 0 0" xyz="-0.285 0.2104 0.035145"/>
    <axis xyz="0 1 0"/>
  </joint>
  <!-- Rear right wheel joint -->
  <joint name="rear_right_wheel" type="fixed">
    <parent link="chassis_link"/>
    <child link="rear_right_wheel_link"/>
    <origin rpy="0 0 0" xyz="-0.285 -0.2104 0.035145"/>
    <axis xyz="0 1 0"/>
  </joint>
  <!-- Mounting points joints -->
  <joint name="mid_mount_joint" type="fixed">
    <origin rpy="0 0 0" xyz="0 0 0.069023"/>
    <parent link="chassis_link"/>
    <child link="mid_mount"/>
  </joint>
  <joint name="front_c_mount_joint" type="fixed">
    <origin rpy="0 0 0" xyz="0.080 0 0"/>
    <parent link="mid_mount"/>
    <child link="front_c_mount"/>
  </joint>
  <joint name="front_b_mount_joint" type="fixed">
    <origin rpy="0 0 0" xyz="0.080 0 0"/>
    <parent link="front_c_mount"/>
    <child link="front_b_mount"/>
  </joint>
  <joint name="front_mount_joint" type="fixed">
    <origin rpy="0 0 0" xyz="0.080 0 0"/>
    <parent link="front_b_mount"/>
    <child link="front_mount"/>
  </joint>
  <joint name="rear_c_mount_joint" type="fixed">
    <origin rpy="0 0 0" xyz="-0.080 0 0"/>
    <parent link="mid_mount"/>
    <child link="rear_c_mount"/>
  </joint>
  <joint name="rear_b_mount_joint" type="fixed">
    <origin rpy="0 0 0" xyz="-0.080 0 0"/>
    <parent link="rear_c_mount"/>
    <child link="rear_b_mount"/>
  </joint>
  <joint name="rear_moint_joint" type="fixed">
    <origin rpy="0 0 0" xyz="-0.080 0 0"/>
    <parent link="rear_b_mount"/>
    <child link="rear_mount"/>
  </joint>
  <joint name="front_bumper_mount_joint" type="fixed">
    <origin rpy="0 0 0" xyz="0.34159 0 0.0345115"/>
    <parent link="chassis_link"/>
    <child link="front_bumper_mount"/>
  </joint>
  
  <!-- Create world joint -->
  <link name="world"/>
  <joint name="world_link" type="fixed">
    <origin rpy="0 0 0" xyz="0 0 0"/>
    <parent link="world"/>
    <child link="base_link"/>
  </joint>
  <joint name="arm_mount_joint" type="fixed">
    <origin rpy="0 0 0" xyz="0 0 0"/>
    <parent link="front_b_mount"/>
    <child link="arm_base_link"/>
  </joint>

</robot>
